Workbook

Sheet Executive Summary
A1: AXC TEAM - OBJECTIVES AND ACTION PLAN
A2: Annual plan | September 2026 - August 2027 | Q1 Sep-Nov 26 . Q2 Dec-Feb 27 . Q3 Mar-May 27 . Q4 Jun-Aug 27
A4: 1 AXC OVERVIEW
A5: Team | C5: AI Transformation Team (AXC)
A6: What we are here to do | C6: AXC gets AI genuinely used in how the company builds software and runs its operations - not by researching AI or building AI products to sell, but by taking AI that already exists and putting it to work inside our own teams. Five kinds of work: - Automate routine work using AI tools that already exist - Set up a library of ready-made templates and tools - Train everyone in the company to use AI in their own role - Work with each project team so AI becomes a normal step in how they build software - Keep AI accounts, spending and data rules under control, with a person responsible for what AI produces We are judged on whether AI is actually being used, not on what was delivered.
A8: 2 TARGETS & EXPECTED OUTCOMES
A9: ID | B9: Target | C9: Weight | D9: Objective | E9: Expected outcomes by Q4 2027 | F9: Owner | G9: Progress | H9: Status
A10: T1 | B10: Apply AI to Everyday Work | C10: ='T1 Apply'!$B$2 -> 0.34 | D10: - Automation workflows - Shared templates & tools | E10: - 5 workflows in live use - CV tool: 8 in 10 CVs - 3 shared assets in use - 3 processes 20% faster | F10: AI Specialist | G10: ='T1 Apply'!$H$49 -> 0.16666667 | H10: =IF('T1 Apply'!$G$2="","Not started",'T1 Apply'!$G$2) -> On track
A11: T2 | B11: Drive Adoption Across Teams | C11: ='T2 Adoption'!$B$2 -> 0.3 | D11: - Named contact per team - Sharing sessions & joint use cases - AI in the dev process - Company-wide training - Internal trainers | E11: - 3 teams engaged - 2 projects with AI in their process - 30% of staff trained (basic) - 70% of trainees using AI - 3 internal trainers | F11: Coordinator | G11: ='T2 Adoption'!$H$44 -> 0.0625 | H11: =IF('T2 Adoption'!$G$2="","Not started",'T2 Adoption'!$G$2) -> On track
A12: T3 | B12: AI Management | C12: ='T3 Management'!$B$2 -> 0.28 | D12: - AI account & cost control - Data rule for AI tools - Human review of AI output - AML company-wide & dashboard | E12: - 100% of accounts mapped - Cost per user down 10% - Zero data incidents - AML in every project (3 today) - AML 2.96 to 3.20 | F12: AXC Lead + Coordinator | G12: ='T3 Management'!$H$41 -> 0.058823529 | H12: =IF('T3 Management'!$G$2="","Not started",'T3 Management'!$G$2) -> On track
A13: T4 | B13: Track & Share New AI | C13: ='T4 Technology'!$B$2 -> 0.08 | D13: - AI tools view - Share new AI tools & tricks - Try out before sharing - Research reports: public / internal | E13: - Tools view, updated quarterly - 2 posts a month - 3 live update sessions - Every research report labelled | F13: AI Specialist + Coordinator | G13: ='T4 Technology'!$H$29 -> 0 | H13: =IF('T4 Technology'!$G$2="","Not started",'T4 Technology'!$G$2) -> On track
B14: TOTAL | C14: =SUM(C10:C13) -> 1 | D14: =IF(ROUND(C14,4)=1,"4 targets, weights add up to 100% - "&((COUNTA('T1 Apply'!$C$20:$C$48)-COUNTIF('T1 Apply'!$B$20:$B$48,"FY27-28"))+(COUNTA('T2 Adoption'!$C$20:$C$43)-COUNTIF('T2 Adoption'!$B$20:$B$43,"FY27-28"))+(COUNTA('T3 Management'!$C$20:$C$40)-COUNTIF('T3 Management'!$B$20:$B$40,"FY27-28"))+(COUNTA('T4 Technology'!$C$17:$C$28)-COUNTIF('T4 Technology'!$B$17:$B$28,"FY27-28")))&" actions this year","ERROR - weights must add up to 100%") -> 4 targets, weights add up to 100% - 52 actions this year | F14: =('T1 Apply'!$E$49+'T2 Adoption'!$E$44+'T3 Management'!$E$41+'T4 Technology'!$E$29)&" of "&((COUNTA('T1 Apply'!$C$20:$C$48)-COUNTIF('T1 Apply'!$B$20:$B$48,"FY27-28"))+(COUNTA('T2 Adoption'!$C$20:$C$43)-COUNTIF('T2 Adoption'!$B$20:$B$43,"FY27-28"))+(COUNTA('T3 Management'!$C$20:$C$40)-COUNTIF('T3 Management'!$B$20:$B$40,"FY27-28"))+(COUNTA('T4 Technology'!$C$17:$C$28)-COUNTIF('T4 Technology'!$B$17:$B$28,"FY27-28")))&" done" -> 4 of 52 done | G14: =IFERROR(('T1 Apply'!$E$49+'T2 Adoption'!$E$44+'T3 Management'!$E$41+'T4 Technology'!$E$29)/((COUNTA('T1 Apply'!$C$20:$C$48)-COUNTIF('T1 Apply'!$B$20:$B$48,"FY27-28"))+(COUNTA('T2 Adoption'!$C$20:$C$43)-COUNTIF('T2 Adoption'!$B$20:$B$43,"FY27-28"))+(COUNTA('T3 Management'!$C$20:$C$40)-COUNTIF('T3 Management'!$B$20:$B$40,"FY27-28"))+(COUNTA('T4 Technology'!$C$17:$C$28)-COUNTIF('T4 Technology'!$B$17:$B$28,"FY27-28"))),0) -> 0.076923077
A15: Sized for the team we actually have: 3 people for the whole year. Every figure in this plan is set against that capacity rather than an ideal team. Work that does not fit is marked FY27-28 on each target sheet and moves to next year's plan rather than being quietly missed; if the team grows, it is brought forward at the next quarter review.
A17: 3 HOW THIS PLAN WORKS
A18: - Weight shows how heavy and how high a priority each target is relative to the others. The four weights add up to 100%. It is a priority signal, not a score.
A19: - Each target sheet holds its actions in quarter order. Every action names what it delivers, and where there is a number to hit, the Success measure column states it.
A20: - Progress is the share of that target's actions marked Done. It counts what is finished, not how much effort went in.
A21: - Status is set by the target owner on their own sheet - Not started, On track, At risk, Behind or Done. Progress counts; status judges.
A22: - Actions marked 'ongoing' run through the whole year rather than landing in one quarter. Actions marked 'FY27-28' are deferred to next year's plan and are not counted in Progress.
A24: 4 HOW TO USE THIS FILE
A25: 1 | B25: Each target has its own sheet (T1 to T4) holding its objective, action plan, approach, dependencies, risks and change history.
A26: 2 | B26: Owners fill in only the yellow cells on their own sheet - the Status of each action, and the target Status at the top.
A27: 3 | B27: This summary updates itself from the four target sheets. Do not type into it.
A28: 4 | B28: To add an action, use one of the two spare rows at the end of the action table rather than inserting a row, and record what you changed in that sheet's Change History.
A29: 5 | B29: Update statuses monthly; review fully at each quarter end.
A30: 6 | B30: Record every approval, confirmation and report from a meeting on the Meeting Log sheet.
A32: 5 DOCUMENT CONTROL
A33: Version | B33: 2.1
A34: Period | B34: September 2026 - August 2027
A35: Prepared by | B35: AXC Team
A36: Last updated | B36: 28/09/2026
A37: Next review | B37: End of Q1 (November 2026)

Sheet T1 Apply
A1: T1 - Apply AI to Everyday Work
A2: Weight | B2: 0.34 | C2: Owner | D2: AI Specialist | F2: Status | G2: On track
A3: Weight shows how heavy and how high a priority this target is relative to the other three. It is not a score.
A5: 1 OBJECTIVE
A6: Put existing AI tools to work in everyday tasks, together with the shared setup underneath them. Automation tools take routine work off each team's hands; the template library stops every team solving the same problem from scratch. Nothing is started until the team that will use it confirms it needs it, and success is judged by whether people are still using it months later.
A8: 2 WHAT THIS MUST ACHIEVE
A9: 1 | B9: Confirm what each team actually needs before setting anything up for them.
A10: 2 | B10: Deliver 1-2 items a month that users have actually tested.
A11: 3 | B11: Make sure each tool is genuinely used after it goes live - delivery alone does not count as success.
A12: 4 | B12: Keep collecting feedback from the teams using the tools, and improve on it.
A13: 5 | B13: Deliver the CV screening tool to the HR office.
A14: 6 | B14: Never set up a shared asset without at least one project committed to using it.
A15: 7 | B15: Keep every asset documented, versioned and owned - and retire the ones nobody uses.
A17: 3 ACTION PLAN
A18: # | B18: Quarter | C18: Action | D18: Deliverable | E18: Success measure | F18: Owner | G18: Due | H18: Status
A19: A. Automation workflows | G19: 0.19
A20: 1 | B20: Q1 | C20: Inventory candidate processes across all teams and survey duties and pain points, ESG and LSG first | D20: Process inventory + needs survey | E20: Every team in scope covered | F20: AI Specialist | G20: Nov 2026
A21: 2 | B21: Q1 | C21: Set up the first workflow (Jira > Google Chat > Sheet) | D21: 1 workflow live | E21: Started only after the using team confirmed the need and a utilization plan | F21: AI Specialist | G21: Nov 2026 | H21: Done
A22: 3 | B22: Q1 | C22: Set up the second workflow: CV screening for HR | D22: CV screening workflow in use | F22: AI Specialist | G22: Nov 2026 | H22: Done
A23: 4 | B23: Q2 | C23: Roll out the CV screening workflow to the whole HR office | D23: CV screening used across the HR office | E23: 8 out of 10 incoming CVs processed through the tool | F23: AI Specialist | G23: Feb 2027 | H23: In progress
A24: 5 | B24: Q2 | C24: Deliver the third workflow | D24: 1 workflow live | E24: Same needs-confirmed gate as the first | F24: AI Specialist | G24: Feb 2027
A25: 6 | B25: Q2 | C25: Track weekly use of every live workflow | D25: Usage tracking live | E25: 8 in 10 target users active at least weekly, one month after launch; user feedback collected monthly | F25: AI Specialist | G25: Feb 2027
A26: 7 | B26: Q3 | C26: Deliver the fourth workflow | D26: 1 workflow live | F26: AI Specialist | G26: May 2027
A27: 8 | B27: FY27-28 | C27: Run a feedback round on every running workflow and act on what comes back | D27: Feedback log + changes made | E27: At least one round per workflow per quarter | F27: AI Specialist | G27: Next year
A28: 9 | B28: Q4 | C28: Measure time saved on the processes the workflows touch | D28: Impact measurement | E28: 3 processes measurably 20% faster | F28: AI Specialist | G28: Aug 2027
A29: 10 | B29: Q4 | C29: Deliver the fifth workflow | D29: 1 workflow live | E29: 5 workflows in live use across the year, CV screening included | F29: AI Specialist | G29: Aug 2027
A30: 11 | B30: FY27-28 | C30: Review the whole set and retire anything that is not being used | D30: Retirement decisions | E30: 9 in 10 workflows still in use three months after launch | F30: AI Specialist | G30: Next year
A31: 12 | B31: Q4 | C31: Produce the value report | D31: Value report | E31: Covers utilization, time saved and three-month survival of every tool; 9 in 10 still in use three months after launch | F31: AI Specialist | G31: Aug 2027
A32: B. Shared tools & templates | G32: 0.15
A33: 13 | B33: Q2 | C33: Release the shared prompt library as the first asset | D33: 1 asset released | F33: AI Specialist | G33: Feb 2027
A34: 14 | B34: Q3 | C34: Release two more assets | D34: 2 assets released | E34: 3 assets released across the year, each used by at least one project | F34: AI Specialist | G34: May 2027
A35: 15 | B35: FY27-28 | C35: Onboard ESG and LSG as the first users of the catalog | D35: 2 teams using shared assets | F35: AI Specialist | G35: Next year
A36: 16 | B36: FY27-28 | C36: Release two more assets | D36: 2 assets released | F36: AI Specialist | G36: Next year
A37: 17 | B37: FY27-28 | C37: Pilot internal document search | D37: Pilot running | E37: Pilot only this year; production next year | F37: AI Specialist | G37: Next year
A38: 18 | B38: FY27-28 | C38: Assess multi-step AI agents for next year | D38: Assessment note | E38: Assessment only - piloting needs more capacity than we have this year | F38: AI Specialist | G38: Next year
A39: 19 | B39: FY27-28 | C39: Release the final asset | D39: 6 assets released across the year | E39: 4 projects using at least one asset, average reuse 2 projects per asset | F39: AI Specialist | G39: Next year
A49: ACTIONS DONE | E49: =COUNTIF(H20:H48,"Done") -> 2 | F49: ="of "&(COUNTA(C20:C48)-COUNTIF(B20:B48,"FY27-28"))&" actions this year" -> of 12 actions this year | G49: Progress | H49: =IFERROR($E49/(COUNTA(C20:C48)-COUNTIF(B20:B48,"FY27-28")),0) -> 0.16666667
A51: 4 HOW WE WILL DO IT
A52: 1 | B52: Workflow Register recording owner, timeline, status, utilization and last-active date for every tool.
A53: 2 | B53: One business contact on the consuming team for every workflow.
...

Sheet T2 Adoption
A1: T2 - Drive Adoption Across Teams
A2: Weight | B2: 0.3 | C2: Owner | D2: Coordinator | F2: Status | G2: On track
A3: Weight shows how heavy and how high a priority this target is relative to the other three. It is not a score.
A5: 1 OBJECTIVE
A6: Get AI into the day-to-day work of the project teams, and into the hands of everyone else in the company. One named contact in each team plus a regular schedule of sharing sessions, so AI becomes a written step in how they build software rather than a personal habit; and a company-wide training programme at three levels, tailored by role. Training counts as successful only when the person actually starts using AI afterwards, and internal trainers are developed early because a team of three cannot train a company on its own.
A8: 2 WHAT THIS MUST ACHIEVE
A9: 1 | B9: Get one named contact from every project team, starting with the two largest groups.
A10: 2 | B10: Run sharing sessions regularly rather than on request.
A11: 3 | B11: Aim for AI to become a normal, written step in how each team builds software.
A12: 4 | B12: Train everyone in the company, not only the development teams.
A13: 5 | B13: Tailor the training to each kind of role and offer three levels of depth.
A14: 6 | B14: Count training as successful only when the person actually starts using AI afterwards.
A15: 7 | B15: Grow internal trainers so the programme does not depend on AXC alone.
A17: 3 ACTION PLAN
A18: # | B18: Quarter | C18: Action | D18: Deliverable | E18: Success measure | F18: Owner | G18: Due | H18: Status
A19: A. Cross-project collaboration | G19: 0.17
A20: 1 | B20: Q1 | C20: Map every group and project, and agree one named contact per group | D20: Group map + contact list | E20: Every group in scope has a named contact | F20: Coordinator | G20: Nov 2026
A21: 2 | B21: Q1 | C21: Kick off with ESG and LSG | D21: Two groups running | E21: ESG and LSG live in Q1 | F21: Coordinator | G21: Nov 2026
A22: 3 | B22: ongoing | C22: Run sharing sessions and workshops on a published schedule | D22: Session records | E22: 6 sessions across the year, one every two months | F22: Coordinator | G22: quarterly | H22: In progress
A23: 4 | B23: Q3 | C23: Bring in the third group | D23: 3 groups engaged | E23: 3 groups actively taking part by year end | F23: Coordinator | G23: May 2027
A24: 5 | B24: Q2 | C24: Start joint use cases with the participating groups | D24: Joint use cases running | E24: 4 joint use cases across the year, delivered jointly and not by AXC alone | F24: Coordinator | G24: Feb 2027 | H24: In progress
A25: 6 | B25: FY27-28 | C25: Form the AI champion network from the named contacts, meeting monthly | D25: Champion network running | F25: Coordinator | G25: Next year
A26: 7 | B26: FY27-28 | C26: Bring in the fourth group | D26: 4 groups engaged | E26: 4 groups actively taking part by year end | F26: Coordinator | G26: Next year
A27: 8 | B27: Q4 | C27: Roll out the AI-in-development checklist to the first two groups | D27: Checklist adopted by 2 groups | E27: AI written into their own process, not left to individual habit; 2 projects using AI as a normal part of how they build software | F27: Coordinator | G27: Aug 2027
A28: 9 | B28: FY27-28 | C28: Extend the checklist to a third group | D28: Checklist adopted by 3 groups | E28: 3 projects using AI as a normal part of how they build software, averaging 3 of the 7 development steps | F28: Coordinator | G28: Next year
A29: 10 | B29: Q4 | C29: Review the year and run the satisfaction survey | D29: Review + survey results | E29: Satisfaction 4 out of 5 | F29: Coordinator | G29: Aug 2027
A30: B. Company-wide training | G30: 0.13
A31: 11 | B31: Q1 | C31: Run the company-wide baseline skill survey | D31: Baseline results | E31: Establishes the starting point for the year | F31: Coordinator + HR | G31: Nov 2026
A32: 12 | B32: Q1 | C32: Prepare the training materials by level and role | D32: Training materials v1.0 | E32: Basic and Advanced decks, plus role demos (QC testing, knowledge system, Workspace) | F32: Coordinator + HR | G32: Nov 2026 | H32: Done
A33: 13 | B33: Q1 | C33: Agree with HR how training is run - schedule, format, sign-up, and where the materials are published | D33: Training plan agreed with HR | E33: Agreed before the pilot starts | F33: Coordinator + HR | G33: Nov 2026
A34: 14 | B34: Q2 | C34: Pilot the basic level with one or two departments | D34: Pilot delivered | F34: Coordinator + HR | G34: Feb 2027
A35: 15 | B35: Q3 | C35: Roll out the basic level on a published schedule | D35: Basic level running company-wide | E35: 3 in 10 of all staff completing it by year end | F35: Coordinator + HR | G35: May 2027
A36: 16 | B36: Q3 | C36: Train 3 internal trainers | D36: 3 internal trainers | E36: 3 trainers able to run courses themselves | F36: Coordinator | G36: May 2027
A37: 17 | B37: FY27-28 | C37: Start the applied level with the development teams | D37: Applied level running | E37: 3 in 10 development staff completing it | F37: Coordinator + HR | G37: Next year
A38: 18 | B38: FY27-28 | C38: Hand most basic-level delivery to the internal trainers | D38: Trainers delivering | F38: Coordinator | G38: Next year
A39: 19 | B39: Q4 | C39: Check that trainees actually use AI after the course | D39: Usage check after training | E39: 7 in 10 trainees using AI within 30 days of the course | F39: Coordinator | G39: Aug 2027
A40: 20 | B40: ongoing | C40: Deliver training sessions and keep the module library current | D40: Session log + modules | E40: 8 sessions across the year; materials kept up to date; 85% completion of enrolled courses; 80% assessment pass; satisfaction 4 out of 5 | F40: Coordinator + HR | G40: quarterly
A41: 21 | B41: Q4 | C41: Review the training year and update the curriculum (v2.0) | D41: Training review + curriculum v2.0 | E41: Weakest role group closer to the strongest: skill gap 0.50 to 0.40 | F41: Coordinator + HR | G41: Aug 2027
A44: ACTIONS DONE | E44: =COUNTIF(H20:H43,"Done") -> 1 | F44: ="of "&(COUNTA(C20:C43)-COUNTIF(B20:B43,"FY27-28"))&" actions this year" -> of 16 actions this year | G44: Progress | H44: =IFERROR($E44/(COUNTA(C20:C43)-COUNTIF(B20:B43,"FY27-28")),0) -> 0.0625
A46: 4 HOW WE WILL DO IT
...

Sheet T3 Management
A1: T3 - AI Management
A2: Weight | B2: 0.28 | C2: Owner | D2: AXC Lead + Coordinator | F2: Status | G2: On track
A3: Weight shows how heavy and how high a priority this target is relative to the other three. It is not a score.
A5: 1 OBJECTIVE
A6: Keep AI use under control and make progress visible to management. Govern who has an AI account, why, what they may spend and what data they may put into it - with a person always reviewing and answerable for AI-produced work. Alongside that, score how far each project has actually come across six areas measured out of 5, published on one dashboard. The governance work delivers exactly what the measurement work scores as the weakest area today.
A8: 2 WHAT THIS MUST ACHIEVE
A9: 1 | B9: Standardise who gets an AI account, why, and how much they may spend.
A10: 2 | B10: Make sure a person always reviews AI-produced work before it is used, and that someone is named as responsible.
A11: 3 | B11: Set clear rules on what company data may and may not be put into AI tools.
A12: 4 | B12: Agree with HR how AI skill is reflected in performance reviews and in hiring.
A13: 5 | B13: Score every project on a fixed schedule, not only when asked.
A14: 6 | B14: Turn each round of scoring into an action plan with a named owner - a score with no action is wasted.
A15: 7 | B15: Report the company-wide picture on one dashboard that management can read at a glance.
A17: 3 ACTION PLAN
A18: # | B18: Quarter | C18: Action | D18: Deliverable | E18: Success measure | F18: Owner | G18: Due | H18: Status
A19: A. Governance, accounts & cost | G19: 0.11
A20: 1 | B20: Q1 | C20: Inventory every AI account and token in use | D20: Account inventory | F20: AXC Lead | G20: Nov 2026 | H20: In progress
A21: 2 | B21: Q1 | C21: Draft the role, purpose and quota matrix and approve the allocation standard | D21: Allocation standard approved | E21: Every account linked to a person, a role and a purpose | F21: AXC Lead | G21: Nov 2026 | H21: In progress
A22: 3 | B22: Q2 | C22: Agree and approve the data rule - what may and may not be sent to AI tools | D22: Data rule approved | E22: 9 in 10 members acknowledge it by Q3; zero data incidents all year | F22: AXC Lead | G22: Feb 2027
A23: 4 | B23: Q2 | C23: Bring the account registry live | D23: Registry live | E23: 100% of accounts mapped to owner, role, purpose and project | F23: AXC Lead | G23: Feb 2027
A24: 5 | B24: Q3 | C24: Set up a human review step for AI output with the first project | D24: Review step + named owner, first project | E24: A person checks AI output before use, and one person is answerable for it | F24: AXC Lead | G24: May 2027
A25: 6 | B25: Q3 | C25: Agree with HR how AI skill is reflected in performance reviews and hiring | D25: Agreed criteria document | F25: AXC Lead + HR | G25: May 2027 | H25: In progress
A26: 7 | B26: Q4 | C26: Apply the human review step to every assessed project | D26: Review step in all assessed projects | E26: Every assessed project has a review step and a named owner for AI output | F26: AXC Lead | G26: Aug 2027
A27: 8 | B27: Q3 | C27: Take back unused AI accounts and check the data rule is followed | D27: Unused accounts taken back + data-rule check | E27: Unused accounts at or below 10%; 9 in 10 taken back or reassigned within a month | F27: AXC Lead | G27: May 2027
A28: 9 | B28: ongoing | C28: Publish the monthly usage and cost report | D28: 12 monthly reports | E28: All 12 on time; total cost within budget; cost per active user down 10% | F28: AXC Lead | G28: monthly
A29: 10 | B29: Q4 | C29: Propose next year's AI budget | D29: Budget proposal | F29: AXC Lead | G29: Aug 2027
A30: B. Maturity measurement & reporting | G30: 0.17
A31: 11 | B31: Q2 | C31: Update the AML framework (v1.1) and publish a self-assessment guide for every project | D31: AML framework v1.1 + guide | E31: Ready before the company-wide rollout | F31: Coordinator | G31: Feb 2027
A32: 12 | B32: Q1 | C32: Score the first 3 projects with AML | D32: AML baseline for 3 projects | E32: 3 projects scored by Q2 | F32: Coordinator | G32: Nov 2026 | H32: Done
A33: 13 | B33: Q2 | C33: Launch the AML dashboard for all assessed projects | D33: AML dashboard live | E33: One page showing every project's AI maturity | F33: Coordinator | G33: Feb 2027
A34: 14 | B34: Q3 | C34: Produce an action plan with a named owner for every assessed project | D34: Action plan per project | E34: 100% of projects - a score with no action is wasted | F34: Coordinator | G34: May 2027
A35: 15 | B35: Q3 | C35: Roll AML out company-wide - every project self-assesses with the guide, AXC checks the result | D35: AML running in all projects | E35: Every active project scored at least once by year end | F35: Coordinator | G35: May 2027
A36: 16 | B36: FY27-28 | C36: Run assessment round two and compare the trend against baseline | D36: Round 2 results | E36: Two rounds per project per year, 9 in 10 completed on schedule | F36: Coordinator | G36: Next year
A37: 17 | B37: FY27-28 | C37: Drive every project's control score to 3.0 or above | D37: Control remediation | E37: The weakest of the six areas, standing at 2.0 today | F37: Coordinator + AXC Lead | G37: Next year
A38: 18 | B38: Q4 | C38: Run the year-end AML round across all projects | D38: Year-end results | E38: Every active project scored; 3 meeting the minimum in all six areas | F38: Coordinator | G38: Aug 2027
A39: 19 | B39: Q4 | C39: Publish the AML progress report | D39: AML progress report | E39: Company-wide score up from 2.96 to 3.20 out of 5 | F39: Coordinator | G39: Aug 2027
A41: ACTIONS DONE | E41: =COUNTIF(H20:H40,"Done") -> 1 | F41: ="of "&(COUNTA(C20:C40)-COUNTIF(B20:B40,"FY27-28"))&" actions this year" -> of 17 actions this year | G41: Progress | H41: =IFERROR($E41/(COUNTA(C20:C40)-COUNTIF(B20:B40,"FY27-28")),0) -> 0.058823529
A43: 4 MATURITY AREAS - SCORE TODAY AND WHO IMPROVES IT
A44: # | B44: Area measured | D44: Today | E44: Minimum | F44: Goal | G44: Improved by | H44: Our aim
A45: 1 | B45: 1. How much of the work AI does | D45: 3.17 | E45: 3 | F45: 4 | G45: T1 | H45: 3.4
...

Sheet T4 Technology
A1: T4 - Track & Share New AI
A2: Weight | B2: 0.08 | C2: Owner | D2: AI Specialist + Coordinator | F2: Status | G2: On track
A3: Weight shows how heavy and how high a priority this target is relative to the other three. It is not a score.
A5: 1 OBJECTIVE
A6: Keep the company up to date with new AI tools, models and practical tricks. AXC watches what is new, tries out what looks useful, and shares it with every team in a short, regular format, so people pick up what helps their own work without waiting for a formal programme. AXC research reports and tool comparisons are shared the same way, each marked public or internal-only.
A8: 2 WHAT THIS MUST ACHIEVE
A9: 1 | B9: Keep an up-to-date view of the AI tools and models in use and worth watching.
A10: 2 | B10: Share new AI tools, tricks and tips with the whole company on a regular schedule.
A11: 3 | B11: Try out promising tools briefly before sharing, so what we share is tested, not hearsay.
A12: 4 | B12: Keep everything shared in one place, each item marked public or internal-only.
A13: 5 | B13: Pass what proves useful to training (T2) and to the shared templates (T1).
A15: 3 ACTION PLAN
A16: # | B16: Quarter | C16: Action | D16: Deliverable | E16: Success measure | F16: Owner | G16: Due | H16: Status
A17: 1 | B17: Q2 | C17: Publish the AI tools view, version 1 - what is in use and what is worth watching | D17: Tools view published | E17: Open to all teams; updated each quarter from Q2 | F17: AI Specialist + Coordinator | G17: Feb 2027
A18: 2 | B18: Q2 | C18: Set up the sharing channel and a searchable archive of everything shared | D18: Channel + archive live | E18: One place every team can find what was shared | F18: Coordinator | G18: Feb 2027
A19: 3 | B19: Q2 | C19: Sort AXC research reports into public and internal-only, and publish the public ones in the archive | D19: Research index: public / internal | E19: Every report labelled; public ones findable by all teams | F19: Coordinator | G19: Feb 2027
A20: 4 | B20: ongoing | C20: Share new AI tools, tricks and tips with the company | D20: Regular posts | E20: At least 2 posts a month from Q2 | F20: AI Specialist + Coordinator | G20: monthly | H20: In progress
A21: 5 | B21: ongoing | C21: Run a short live AI update session each quarter | D21: Session records | E21: 3 sessions across the year, from Q2 | F21: Coordinator | G21: quarterly
A22: 6 | B22: Q3 | C22: Try out promising new tools before sharing them | D22: Try-out notes | E22: One page per try-out: what it does, what it costs, who it suits | F22: AI Specialist | G22: May 2027
A23: 7 | B23: Q4 | C23: Review the year - what was shared, what teams picked up - and update the view | D23: Year-end view + feedback | E23: Keeping-up-with-new-AI score up from 2.81 to 2.95 out of 5 | F23: AI Specialist + Coordinator | G23: Aug 2027
A29: ACTIONS DONE | E29: =COUNTIF(H17:H28,"Done") -> 0 | F29: ="of "&(COUNTA(C17:C28)-COUNTIF(B17:B28,"FY27-28"))&" actions this year" -> of 7 actions this year | G29: Progress | H29: =IFERROR($E29/(COUNTA(C17:C28)-COUNTIF(B17:B28,"FY27-28")),0) -> 0
A31: 4 HOW WE WILL DO IT
A32: 1 | B32: A one-page tools view - in use, worth watching, not recommended - updated each quarter and open to all teams.
A33: 2 | B33: One sharing channel for short posts: what the tool or trick is, what it helps with, and how to start.
A34: 3 | B34: A searchable archive, so anything shared can be found again later.
A35: 4 | B35: Quick try-outs in a separate sandbox; no production or customer data in any tool not yet approved under T3.
A36: 5 | B36: Useful items passed to T2 for training material and to T1 for templates - no formal handover.
A37: 6 | B37: A short live update each quarter for anyone who prefers to see it demonstrated.
A39: 5 WHAT THIS DEPENDS ON
A40: 1 | B40: T2 - the training curriculum picks up what proves useful
A41: 2 | B41: T3 - the data rule and cost limits bound what can be tried out
A42: 3 | B42: T1 - useful tricks become shared templates
A44: 6 LINK TO THE MATURITY SCORE
A45: Raises the 'keeping up with new AI' measure inside Axis 4, which at 2.81 is the lowest-scoring single measure in the whole framework, with 13 of 43 people rating themselves at 2 or below.
A47: 7 RISK & MITIGATION
A48: # | B48: Risk | E48: How we handle it
A49: 1 | B49: Sharing turns into noise nobody reads | E49: Short posts, only items we have tried ourselves, and the archive shows what people actually open
A50: 2 | B50: Try-out cost grows unchecked | E50: Free or trial tiers only; anything paid needs approval under T3
A52: 8 CHANGE HISTORY
A53: Log every change to this target here - an action added or dropped, a success measure revised, a date moved, or a change of scope. Keep the original wording in the Reason column.
...

Sheet Meeting Log
A1: MEETING LOG - record of approvals, confirmations and reports
A2: Add one row each time something is approved, confirmed, reported or deferred at a meeting. This is the written record of what was agreed, so decisions do not have to be reconstructed from memory later.
A4: 1 HOW TO FILL THIS IN
A5: 1 | B5: One row per decision, not one row per meeting. If a meeting approves two things, that is two rows.
A6: 2 | B6: Outcome says what happened: Approved (a decision was granted), Confirmed (an update was accepted), Reported (information given, nothing decided), Deferred (pushed to a later meeting), Rejected (turned down).
A7: 3 | B7: Write what was actually said - keep the original wording rather than summarising it away.
A8: 4 | B8: If the decision creates work, put it in the follow-up column with an owner and a due date, and set Status to Open. Change it to Done once closed.
A9: 5 | B9: Use role names rather than personal names in the Owner column.
A11: 2 LOG
A12: # | B12: Date | C12: Meeting | D12: Target | E12: Outcome | F12: What was decided or reported | G12: Follow-up action | H12: Owner (role) | I12: Due | J12: Status
A13: 1 | B13: 2026-09-24 | C13: MC meeting | D13: T1 | E13: Confirmed | F13: EXAMPLE ROW - delete before use. Automation backlog and per-item timeline accepted; asked that the two largest groups be surveyed first. | G13: Survey ESG and LSG duties before starting setup | H13: Coordinator | I13: 2026-10-15 | J13: Done
A14: 2
A15: 3
A16: 4
A17: 5
A18: 6
A19: 7
A20: 8
A21: 9
A22: 10
A23: 11
A24: 12
A25: 13
... A43: 31

Sheet Note
