Workbook

Sheet Executive Summary
A1: q
A2: Annual plan | September 2026 - August 2027 | Q1 Sep-Nov 26 . Q2 Dec-Feb 27 . Q3 Mar-May 27 . Q4 Jun-Aug 27
A4: 1 AXC OVERVIEW
A5: Team | C5: AI Transformation Team (AXC)
A6: What we are here to do | C6: AXC gets AI genuinely used in how the company builds software and runs its operations - not by researching AI or building AI products to sell, but by taking AI that already exists and putting it to work inside our own teams. Five kinds of work: - Build automation tools ourselves rather than buying them - Build the shared groundwork and a library of ready-made templates and tools - Train everyone in the company to use AI in their own role - Work with each project team so AI becomes a normal step in how they build software - Keep AI accounts, spending and data rules under control, with a person responsible for what AI produces We are judged on whether AI is actually being used, not on what was delivered.
A8: 2 TARGETS & EXPECTED OUTCOMES
A9: ID | B9: Target | C9: Weight | D9: Objective | E9: Expected outcomes by Q4 2027 | F9: Owner | G9: Progress | H9: Status
A10: T1 | B10: Build AI Tools & Automation | C10: ='T1 Build'!$B$2 -> 0.34 | D10: - Automation tools built in-house, not bought - CV screening tool for the HR office - A shared AI gateway everything runs through - A library of ready-made templates and tools - Built only on confirmed need; judged on real use | E10: 5 automation flows in live use, 9 in 10 still in use three months after launch. | CV screening tool running at the HR office, handling 8 out of 10 incoming CVs. | Shared AI gateway in production; 6 ready-made templates used by at least 4 projects. | 3 processes measurably 20% faster. | F10: Developer | G10: ='T1 Build'!$H$49 -> 0 | H10: =IF('T1 Build'!$G$2="","Not started",'T1 Build'!$G$2) -> Not started
A11: T2 | B11: Drive Adoption Across Teams | C11: ='T2 Adoption'!$B$2 -> 0.3 | D11: - One named contact in every project team - Regular sharing sessions and joint use cases - AI written into how each team builds software - Company-wide training, three levels, by role - Internal trainers, so it does not rest on AXC | E11: 4 teams actively taking part, each with a named contact; 3 projects using AI as a normal part of how they build software. | Half of all staff trained to the basic level, 3 in 10 development staff to the applied level. | 7 in 10 trainees using AI within a month. | 3 internal trainers running courses themselves. | F11: Coordinator | G11: ='T2 Adoption'!$H$44 -> 0 | H11: =IF('T2 Adoption'!$G$2="","Not started",'T2 Adoption'!$G$2) -> Not started
A12: T3 | B12: AI Management | C12: ='T3 Management'!$B$2 -> 0.28 | D12: - Who holds an AI account, why, at what cost - Clear rules on what data may go into AI tools - A person reviews and answers for AI output - Every project scored across six areas - One dashboard management can read at a glance | E12: Every AI account linked to a person, a role and a purpose; a review step and a named responsible person across all projects; cost per user down 10%; no data incidents. | 5 projects scored, 3 meeting the minimum in all six areas. | Company-wide maturity score up from 2.96 to 3.30 out of 5. | F12: AXC Lead + Coordinator | G12: ='T3 Management'!$H$41 -> 0 | H12: =IF('T3 Management'!$G$2="","Not started",'T3 Management'!$G$2) -> Not started
A13: T4 | B13: Track Technology | C13: ='T4 Technology'!$B$2 -> 0.08 | D13: - A published view of what we adopt, trial or avoid - Four reviews a year, each ending in a decision - Free alternatives to paid tools looked at first - Every adoption handed to a named owner | E13: A quarterly published view of which AI technologies we adopt, trial or avoid. | 4 reviews completed, each ending in a decision, with 4 in 10 leading to something we actually use. | At least one paid tool replaced by a free alternative. | F13: Developer + Coordinator | G13: ='T4 Technology'!$H$29 -> 0 | H13: =IF('T4 Technology'!$G$2="","Not started",'T4 Technology'!$G$2) -> Not started
B14: TOTAL | C14: =SUM(C10:C13) -> 1 | D14: =IF(ROUND(C14,4)=1,"4 targets, weights add up to 100% - 75 actions in total","ERROR - weights must add up to 100%") -> 4 targets, weights add up to 100% - 75 actions in total | F14: =('T1 Build'!$E$49+'T2 Adoption'!$E$44+'T3 Management'!$E$41+'T4 Technology'!$E$29)&" of 75 done" -> 0 of 75 done | G14: =IFERROR(('T1 Build'!$E$49+'T2 Adoption'!$E$44+'T3 Management'!$E$41+'T4 Technology'!$E$29)/75,0) -> 0
A15: Sized for the team we actually have: 3 people today, rising to 5 by December 2026. Every figure in this plan is set against that capacity rather than an ideal team. If hiring slips, the affected targets are rescoped at the Q3 review rather than quietly missed.
A17: 3 HOW THIS PLAN WORKS
A18: - Weight shows how heavy and how high a priority each target is relative to the others. The four weights add up to 100%. It is a priority signal, not a score.
A19: - Each target sheet holds its actions in quarter order. Every action names what it delivers, and where there is a number to hit, the Success measure column states it.
A20: - Progress is the share of that target's actions marked Done. It counts what is finished, not how much effort went in.
A21: - Status is set by the target owner on their own sheet - Not started, On track, At risk, Behind or Done. Progress counts; status judges.
A22: - Actions marked 'ongoing' run through the whole year rather than landing in one quarter.
A24: 4 HOW TO USE THIS FILE
A25: 1 | B25: Each target has its own sheet (T1 to T4) holding its objective, action plan, approach, dependencies, risks and change history.
A26: 2 | B26: Owners fill in only the yellow cells on their own sheet - the Status of each action, and the target Status at the top.
A27: 3 | B27: This summary updates itself from the four target sheets. Do not type into it.
A28: 4 | B28: To add an action, use one of the two spare rows at the end of the action table rather than inserting a row, and record what you changed in that sheet's Change History.
A29: 5 | B29: Update statuses monthly; review fully at each quarter end.
A30: 6 | B30: Record every approval, confirmation and report from a meeting on the Meeting Log sheet.
A32: 5 DOCUMENT CONTROL
A33: Version | B33: 2.0
A34: Period | B34: September 2026 - August 2027
A35: Prepared by | B35: AXC Team
A36: Last updated
A37: Next review | B37: End of Q1 (November 2026)

Sheet T1 Build
A1: T1 - Build AI Tools & Automation
A2: Weight | B2: 0.34 | C2: Owner | D2: Developer | F2: Status
A3: Weight shows how heavy and how high a priority this target is relative to the other three. It is not a score.
A5: 1 OBJECTIVE
A6: Build the tools that put AI into everyday work, together with the shared groundwork underneath them. Automation tools take routine work off each team's hands; the shared gateway and template library stop every team solving the same problem from scratch. Nothing is built until the team that will use it confirms it needs it, and success is judged by whether people are still using it months later.
A8: 2 WHAT THIS MUST ACHIEVE
A9: 1 | B9: Confirm what each team actually needs before building anything for them.
A10: 2 | B10: Give every item on the backlog a clear timeline and a named owner.
A11: 3 | B11: Make sure each tool is genuinely used after it goes live - delivery alone does not count as success.
A12: 4 | B12: Keep collecting feedback from the teams using the tools, and improve on it.
A13: 5 | B13: Deliver the CV screening tool to the HR office.
A14: 6 | B14: Never build a shared asset without at least one project committed to using it.
A15: 7 | B15: Keep every asset documented, versioned and owned - and retire the ones nobody uses.
A17: 3 ACTION PLAN
A18: # | B18: Quarter | C18: Action | D18: Deliverable | E18: Success measure | F18: Owner | G18: Due | H18: Status
A19: A. Automation workflows | G19: 0.19
A20: 1 | B20: Q1 | C20: Inventory candidate processes across all teams and survey duties and pain points, ESG and LSG first | D20: Process inventory + needs survey | E20: Every team in scope covered | F20: Developer | G20: Nov 2026
A21: 2 | B21: Q1 | C21: Prioritise the backlog by impact against effort, and set a timeline and owner for each item | D21: Prioritised backlog | E21: 100% of items carry a timeline and a named owner | F21: Developer | G21: Nov 2026
A22: 3 | B22: Q1 | C22: Build the first workflow | D22: 1 workflow live | E22: Built only after the using team confirmed the need and a utilization plan | F22: Developer | G22: Nov 2026
A23: 4 | B23: Q1 | C23: Start building the CV screening tool | D23: CV tool in build | F23: Developer | G23: Nov 2026
A24: 5 | B24: Q2 | C24: Roll out the CV screening tool to the HR office | D24: CV tool live at the HR office | E24: 8 out of 10 incoming CVs processed through the tool | F24: Developer | G24: Feb 2027
A25: 6 | B25: Q2 | C25: Deliver the second workflow | D25: 1 workflow live | E25: Same needs-confirmed gate as the first | F25: Developer | G25: Feb 2027
A26: 7 | B26: Q2 | C26: Stand up utilization tracking on every live workflow | D26: Utilization tracking live | E26: 8 in 10 target users active at least weekly, one month after launch | F26: Developer | G26: Feb 2027
A27: 8 | B27: Q3 | C27: Deliver the third workflow | D27: 1 workflow live | F27: Developer | G27: May 2027
A28: 9 | B28: Q3 | C28: Run a feedback round on every running workflow and act on what comes back | D28: Feedback log + changes made | E28: At least one round per workflow per quarter | F28: Developer | G28: May 2027
A29: 10 | B29: Q3 | C29: Measure time saved on the processes the workflows touch | D29: Impact measurement | E29: 3 processes measurably 20% faster | F29: Developer | G29: May 2027
A30: 11 | B30: Q4 | C30: Deliver the fourth workflow | D30: 1 workflow live | E30: 5 automation tools in live use across the year | F30: Developer | G30: Aug 2027
A31: 12 | B31: Q4 | C31: Review the whole set and retire anything that is not being used | D31: Retirement decisions | E31: 9 in 10 workflows still in use three months after launch | F31: Developer | G31: Aug 2027
A32: 13 | B32: Q4 | C32: Produce the value report | D32: Value report | F32: Developer | G32: Aug 2027
A33: B. Shared tools & building blocks | G33: 0.15
A34: 14 | B34: Q1 | C34: Produce the shared tooling roadmap with costs and get it approved | D34: Roadmap + cost estimate, approved | E34: Approved before any build starts | F34: Developer | G34: Nov 2026
A35: 15 | B35: Q1 | C35: Stand up the central catalog and the packaging standard | D35: Catalog live + packaging standard | E35: Every asset carries a README, a runnable example, an owner and a version | F35: Developer | G35: Nov 2026
A36: 16 | B36: Q1 | C36: Release the shared prompt library as the first asset | D36: 1 asset released | F36: Developer | G36: Nov 2026
A37: 17 | B37: Q2 | C37: Take the shared AI gateway to production | D37: Gateway in production | E37: One shared way in to the AI models; cuts cost | F37: Developer | G37: Feb 2027
A38: 18 | B38: Q2 | C38: Release two more assets | D38: 2 assets released | F38: Developer | G38: Feb 2027
A39: 19 | B39: Q2 | C39: Onboard ESG and LSG as the first users of the catalog | D39: 2 teams using shared assets | F39: Developer | G39: Feb 2027
A40: 20 | B40: Q3 | C40: Document the data-rule controls and apply them to the shared tooling | D40: Data-rule controls in place | E40: Applies the rule agreed under AI Management | F40: Developer | G40: May 2027
A41: 21 | B41: Q3 | C41: Release two more assets | D41: 2 assets released | F41: Developer | G41: May 2027
A42: 22 | B42: Q3 | C42: Open contribution from teams outside AXC and review what comes in | D42: Contribution process live | E42: 2 assets contributed from outside AXC by year end | F42: Developer | G42: May 2027
A43: 23 | B43: Q4 | C43: Pilot internal document search | D43: Pilot running | E43: Pilot only this year; production next year | F43: Developer | G43: Aug 2027
...

Sheet T2 Adoption
A1: T2 - Drive Adoption Across Teams
A2: Weight | B2: 0.3 | C2: Owner | D2: Coordinator | F2: Status
A3: Weight shows how heavy and how high a priority this target is relative to the other three. It is not a score.
A5: 1 OBJECTIVE
A6: Get AI into the day-to-day work of the project teams, and into the hands of everyone else in the company. One named contact in each team plus a regular schedule of sharing sessions, so AI becomes a written step in how they build software rather than a personal habit; and a company-wide training programme at three levels, tailored by role. Training counts as successful only when the person actually starts using AI afterwards, and internal trainers are developed early because a team of five cannot train a company on its own.
A8: 2 WHAT THIS MUST ACHIEVE
A9: 1 | B9: Get one named contact from every project team, starting with the two largest groups.
A10: 2 | B10: Run sharing sessions regularly rather than on request.
A11: 3 | B11: Aim for AI to become a normal, written step in how each team builds software.
A12: 4 | B12: Train everyone in the company, not only the development teams.
A13: 5 | B13: Tailor the training to each kind of role and offer three levels of depth.
A14: 6 | B14: Count training as successful only when the person actually starts using AI afterwards.
A15: 7 | B15: Build internal trainers so the programme does not depend on AXC alone.
A17: 3 ACTION PLAN
A18: # | B18: Quarter | C18: Action | D18: Deliverable | E18: Success measure | F18: Owner | G18: Due | H18: Status
A19: A. Cross-project collaboration | G19: 0.17
A20: 1 | B20: Q1 | C20: Map every group and project, and agree one named contact per group | D20: Group map + contact list | E20: Every group in scope has a named contact | F20: Coordinator | G20: Nov 2026
A21: 2 | B21: Q1 | C21: Kick off with ESG and LSG | D21: Two groups running | E21: ESG and LSG live in Q1 | F21: Coordinator | G21: Nov 2026
A22: 3 | B22: Q1 | C22: Open the action and blocker tracker, visible to all participating groups | D22: Tracker live | E22: 8 in 10 cross-team blockers addressed; 8 in 10 actions closed on time | F22: Coordinator | G22: Nov 2026
A23: 4 | B23: ongoing | C23: Run sharing sessions and workshops on a published schedule | D23: Session records | E23: 12 sessions across the year, about one a month | F23: Coordinator | G23: quarterly
A24: 5 | B24: Q2 | C24: Bring in the third group | D24: 3 groups engaged | F24: Coordinator | G24: Feb 2027
A25: 6 | B25: Q2 | C25: Start joint use cases with the participating groups | D25: Joint use cases running | E25: 4 joint use cases across the year, delivered jointly and not by AXC alone | F25: Coordinator | G25: Feb 2027
A26: 7 | B26: Q2 | C26: Form the AI champion network from the named contacts, meeting monthly | D26: Champion network running | F26: Coordinator | G26: Feb 2027
A27: 8 | B27: Q3 | C27: Bring in the fourth group | D27: 4 groups engaged | E27: 4 groups actively taking part by year end | F27: Coordinator | G27: May 2027
A28: 9 | B28: Q3 | C28: Roll out the AI-in-development checklist to the first two groups | D28: Checklist adopted by 2 groups | E28: AI written into their own process, not left to individual habit | F28: Coordinator | G28: May 2027
A29: 10 | B29: Q4 | C29: Extend the checklist to a third group | D29: Checklist adopted by 3 groups | E29: 3 projects using AI as a normal part of how they build software, averaging 3 of the 7 development steps | F29: Coordinator | G29: Aug 2027
A30: 11 | B30: Q4 | C30: Review the year and run the satisfaction survey | D30: Review + survey results | E30: Satisfaction 4 out of 5 | F30: Coordinator | G30: Aug 2027
A31: B. Company-wide training | G31: 0.13
A32: 12 | B32: Q1 | C32: Run the company-wide baseline skill survey | D32: Baseline results | E32: Establishes the starting point for the year | F32: Coordinator + HR | G32: Nov 2026
A33: 13 | B33: Q1 | C33: Design the curriculum by role and level, and get version 1.0 approved | D33: Curriculum v1.0 | E33: Three levels, branching by role, covering non-technical staff too | F33: Coordinator + HR | G33: Nov 2026
A34: 14 | B34: Q1 | C34: Pilot the basic level with one or two departments | D34: Pilot delivered | F34: Coordinator + HR | G34: Nov 2026
A35: 15 | B35: Q2 | C35: Roll out the basic level on a published schedule | D35: Basic level running company-wide | E35: Half of all staff completing it by year end | F35: Coordinator + HR | G35: Feb 2027
A36: 16 | B36: Q2 | C36: Run train-the-trainer early so delivery does not depend on AXC alone | D36: 3 internal trainers | E36: 3 trainers able to run courses themselves - the only way to scale with a team of five | F36: Coordinator | G36: Feb 2027
A37: 17 | B37: Q2 | C37: Start the applied level with the development teams | D37: Applied level running | E37: 3 in 10 development staff completing it | F37: Coordinator + HR | G37: Feb 2027
A38: 18 | B38: Q3 | C38: Hand most basic-level delivery to the internal trainers | D38: Trainers delivering | F38: Coordinator | G38: May 2027
A39: 19 | B39: Q3 | C39: Measure conversion from training into actual use | D39: Conversion report | E39: 7 in 10 trainees with an active AI account within 30 days of the course | F39: Coordinator | G39: May 2027
A40: 20 | B40: ongoing | C40: Deliver training sessions and keep the module library current | D40: Session log + modules | E40: 12 sessions across the year; 6 reusable modules; 85% completion of enrolled courses; 80% assessment pass; satisfaction 4 out of 5 | F40: Coordinator + HR | G40: quarterly
A41: 21 | B41: Q4 | C41: Assess the year, issue curriculum version 2.0 and plan next year | D41: Year assessment + v2.0 | E41: Skill gap between the strongest and weakest role group down from 0.50 to 0.35 or less | F41: Coordinator + HR | G41: Aug 2027
A44: ACTIONS DONE | E44: =COUNTIF(H20:H43,"Done") -> 0 | F44: ="of 21 actions" -> of 21 actions | G44: Progress | H44: =IFERROR($E44/21,0) -> 0
A46: 4 HOW WE WILL DO IT
...

Sheet T3 Management
A1: T3 - AI Management
A2: Weight | B2: 0.28 | C2: Owner | D2: AXC Lead + Coordinator | F2: Status
A3: Weight shows how heavy and how high a priority this target is relative to the other three. It is not a score.
A5: 1 OBJECTIVE
A6: Keep AI use under control and make progress visible to management. Govern who has an AI account, why, what they may spend and what data they may put into it - with a person always reviewing and answerable for AI-produced work. Alongside that, score how far each project has actually come across six areas measured out of 5, published on one dashboard. The governance work delivers exactly what the measurement work scores as the weakest area today.
A8: 2 WHAT THIS MUST ACHIEVE
A9: 1 | B9: Standardise who gets an AI account, why, and how much they may spend.
A10: 2 | B10: Make sure a person always reviews AI-produced work before it is used, and that someone is named as responsible.
A11: 3 | B11: Set clear rules on what company data may and may not be put into AI tools.
A12: 4 | B12: Agree with HR how AI skill is reflected in performance reviews and in hiring.
A13: 5 | B13: Score every project on a fixed schedule, not only when asked.
A14: 6 | B14: Turn each round of scoring into an action plan with a named owner - a score with no action is wasted.
A15: 7 | B15: Report the company-wide picture on one dashboard that management can read at a glance.
A17: 3 ACTION PLAN
A18: # | B18: Quarter | C18: Action | D18: Deliverable | E18: Success measure | F18: Owner | G18: Due | H18: Status
A19: A. Governance, accounts & cost | G19: 0.11
A20: 1 | B20: Q1 | C20: Inventory every AI account and token in use | D20: Account inventory | F20: AXC Lead | G20: Nov 2026
A21: 2 | B21: Q1 | C21: Build the role, purpose and quota matrix and approve the allocation standard | D21: Allocation standard approved | E21: Every account linked to a person, a role and a purpose | F21: AXC Lead | G21: Nov 2026
A22: 3 | B22: Q1 | C22: Agree and approve the data rule - what may and may not be sent to AI tools | D22: Data rule approved | E22: 9 in 10 members acknowledge it by Q2; zero data incidents all year | F22: AXC Lead | G22: Nov 2026
A23: 4 | B23: Q2 | C23: Bring the account registry live | D23: Registry live | E23: 100% of accounts mapped to owner, role, purpose and project | F23: AXC Lead | G23: Feb 2027
A24: 5 | B24: Q2 | C24: Draft the review gate and the accountability matrix with the first project | D24: Draft gate + matrix | E24: A person reviews AI output before it is used, and a named person is answerable for it | F24: AXC Lead | G24: Feb 2027
A25: 6 | B25: Q3 | C25: Agree with HR how AI skill is reflected in performance reviews and hiring | D25: Agreed criteria document | F25: AXC Lead + HR | G25: May 2027
A26: 7 | B26: Q3 | C26: Roll the review gate and accountability matrix out to all projects | D26: Gate live everywhere | E26: 100% of projects have a review step and a named owner for AI output | F26: AXC Lead | G26: May 2027
A27: 8 | B27: Q3 | C27: Run the reclaim cycle and audit compliance with the data rule | D27: Reclaim + audit report | E27: Idle accounts at or below 10%; 9 in 10 reclaimed or reallocated within a month | F27: AXC Lead | G27: May 2027
A28: 9 | B28: ongoing | C28: Publish the monthly usage and cost report | D28: 12 monthly reports | E28: All 12 on time; total cost within budget; cost per active user down 10% | F28: AXC Lead | G28: monthly
A29: 10 | B29: Q4 | C29: Review cost, propose next year's budget and run the annual audit | D29: Budget proposal + audit | F29: AXC Lead | G29: Aug 2027
A30: B. Maturity measurement & reporting | G30: 0.17
A31: 11 | B31: Q1 | C31: Release framework version 1.1 - correct the scoring formulas and add the missing role scales | D31: Framework v1.1 | E31: Ready before the first assessment round | F31: Coordinator | G31: Nov 2026
A32: 12 | B32: Q1 | C32: Establish the portfolio baseline and extend assessment to two more projects | D32: Baseline published | E32: 3 projects scored by Q2 | F32: Coordinator | G32: Nov 2026
A33: 13 | B33: Q2 | C33: Launch the portfolio dashboard covering every assessed project | D33: Dashboard live | E33: One dashboard showing the whole company picture | F33: Coordinator | G33: Feb 2027
A34: 14 | B34: Q2 | C34: Produce an action plan with a named owner for every assessed project | D34: Action plan per project | E34: 100% of projects - a score with no action is wasted | F34: Coordinator | G34: Feb 2027
A35: 15 | B35: Q3 | C35: Run assessment round two and compare the trend against baseline | D35: Round 2 results | E35: Two rounds per project per year, 9 in 10 completed on schedule | F35: Coordinator | G35: May 2027
A36: 16 | B36: Q3 | C36: Drive every project's control score to 3.0 or above | D36: Control remediation | E36: The weakest of the six areas, standing at 2.0 today | F36: Coordinator + AXC Lead | G36: May 2027
A37: 17 | B37: Q4 | C37: Run the year-end round across at least five projects | D37: Year-end results | E37: 5 projects scored; 3 meeting the minimum in all six areas; 2 areas at goal level at CARIS | F37: Coordinator | G37: Aug 2027
A38: 18 | B38: Q4 | C38: Publish the growth report and issue framework version 2.0 for next year | D38: Growth report + v2.0 | E38: Company-wide score up from 2.96 to 3.30 out of 5 | F38: Coordinator | G38: Aug 2027
A41: ACTIONS DONE | E41: =COUNTIF(H20:H40,"Done") -> 0 | F41: ="of 18 actions" -> of 18 actions | G41: Progress | H41: =IFERROR($E41/18,0) -> 0
A43: 4 MATURITY AREAS - SCORE TODAY AND WHO IMPROVES IT
A44: # | B44: Area measured | D44: Today | E44: Minimum | F44: Goal | G44: Improved by | H44: Our aim
A45: 1 | B45: 1. How much of the work AI does | D45: 3.17 | E45: 3 | F45: 4 | G45: T1 | H45: 3.6
A46: 2 | B46: 2. Whether quality holds up | D46: 3.31 | E46: 3 | F46: 4 | G46: T1, T2 | H46: 3.6
...

Sheet T4 Technology
A1: T4 - Track Technology
A2: Weight | B2: 0.08 | C2: Owner | D2: Developer + Coordinator | F2: Status
A3: Weight shows how heavy and how high a priority this target is relative to the other three. It is not a score.
A5: 1 OBJECTIVE
A6: Keep track of new AI tools and models and decide which are worth adopting, so the company neither falls behind nor chases every new release. Each review starts from a real need, finishes within two weeks, and ends with a clear yes or no. Cheaper free alternatives to tools we currently pay for are looked at first, and anything adopted is handed to a named owner who turns it into something usable.
A8: 2 WHAT THIS MUST ACHIEVE
A9: 1 | B9: Keep a published, up-to-date view of which AI technologies we adopt, trial, or avoid.
A10: 2 | B10: Start every review from a real need - never review something out of curiosity.
A11: 3 | B11: Finish each review within two weeks and end it with a clear yes or no.
A12: 4 | B12: Look first at free alternatives to tools we currently pay for.
A13: 5 | B13: Hand every adopted technology to a named owner who turns it into something usable.
A15: 3 ACTION PLAN
A16: # | B16: Quarter | C16: Action | D16: Deliverable | E16: Success measure | F16: Owner | G16: Due | H16: Status
A17: 1 | B17: Q1 | C17: Build the technology view, version 1, covering what is in use and what is under consideration | D17: Technology view published | E17: Four rings: adopt, trial, assess, avoid - visible to all teams | F17: Developer + Coordinator | G17: Nov 2026
A18: 2 | B18: Q1 | C18: Standardise the review template and the entry gate | D18: Template + gate in place | E18: No named use case, no review opened | F18: Developer + Coordinator | G18: Nov 2026
A19: 3 | B19: Q1 | C19: Run the first review - a free alternative to a tool we pay for | D19: 1 review closed | E19: Finished within two weeks, ending in a clear yes or no | F19: Developer + Coordinator | G19: Nov 2026
A20: 4 | B20: Q2 | C20: Run the second review and update the published view | D20: 1 review closed + view updated | F20: Developer + Coordinator | G20: Feb 2027
A21: 5 | B21: Q2 | C21: Submit the first adoption proposal | D21: Proposal submitted | F21: Coordinator | G21: Feb 2027
A22: 6 | B22: Q2 | C22: Hand every adopted technology to a named owner who turns it into something usable | D22: Handover records | E22: 4 in 10 adopted reviews become a real asset within a quarter | F22: Developer + Coordinator | G22: Feb 2027
A23: 7 | B23: Q3 | C23: Run the third review, and re-check whether already-adopted technology is still the right choice | D23: 1 review closed + re-check | F23: Developer + Coordinator | G23: May 2027
A24: 8 | B24: ongoing | C24: Deliver a technology briefing to the teams each quarter | D24: 4 briefings | E24: One per quarter, feeding the training curriculum in T2 | F24: Coordinator | G24: quarterly
A25: 9 | B25: Q4 | C25: Run the fourth review and submit the second adoption proposal | D25: 1 review closed + proposal | E25: 4 reviews across the year, each ending in a decision; at least 1 proposal approved; at least 1 paid tool replaced by a free alternative | F25: Developer + Coordinator | G25: Aug 2027
A26: 10 | B26: Q4 | C26: Publish the year-end view and propose next year's technology direction | D26: Year-end view + direction | E26: View updated all four quarters; no review left running past the two-week limit; score on keeping up with new AI up from 2.81 to 3.10 out of 5 | F26: Developer + Coordinator | G26: Aug 2027
A29: ACTIONS DONE | E29: =COUNTIF(H17:H28,"Done") -> 0 | F29: ="of 10 actions" -> of 10 actions | G29: Progress | H29: =IFERROR($E29/10,0) -> 0
A31: 4 HOW WE WILL DO IT
A32: 1 | B32: A one-page technology view with four rings - adopt, trial, assess, avoid - updated quarterly, open to all teams.
A33: 2 | B33: A mandatory review template: named use case, criteria, time limit, cost cap, conclusion, and the owner who receives the result.
A34: 3 | B34: Entry gate: without a named use case a review cannot be opened. This is the control against open-ended work.
A35: 4 | B35: A separate sandbox; no production or customer data until a security review is passed.
A36: 5 | B36: Mandatory handover on adoption: to T1 for packaging or a workflow, or to T2 for the curriculum.
A37: 6 | B37: Free alternatives looked at first, tied to the cost-per-user goal under T3.
A39: 5 WHAT THIS DEPENDS ON
A40: 1 | B40: T1 - takes adopted technology and turns it into a usable asset
A41: 2 | B41: T3 - the data rule and cost limits bound what can be trialled
A42: 3 | B42: T2 - supplies the real needs that justify opening a review
A44: 6 LINK TO THE MATURITY SCORE
A45: Raises the 'keeping up with new AI' measure inside Axis 4, which at 2.81 is the lowest-scoring single measure in the whole framework, with 13 of 43 people rating themselves at 2 or below.
A47: 7 RISK & MITIGATION
A48: # | B48: Risk | E48: How we handle it
A49: 1 | B49: Seen as research rather than delivery | E49: A named use case is required to open a review, every review is time limited, and the share that turns into something real is measured
...

Sheet Meeting Log
A1: MEETING LOG - record of approvals, confirmations and reports
A2: Add one row each time something is approved, confirmed, reported or deferred at a meeting. This is the written record of what was agreed, so decisions do not have to be reconstructed from memory later.
A4: 1 HOW TO FILL THIS IN
A5: 1 | B5: One row per decision, not one row per meeting. If a meeting approves two things, that is two rows.
A6: 2 | B6: Outcome says what happened: Approved (a decision was granted), Confirmed (an update was accepted), Reported (information given, nothing decided), Deferred (pushed to a later meeting), Rejected (turned down).
A7: 3 | B7: Write what was actually said - keep the original wording rather than summarising it away.
A8: 4 | B8: If the decision creates work, put it in the follow-up column with an owner and a due date, and set Status to Open. Change it to Done once closed.
A9: 5 | B9: Use role names rather than personal names in the Owner column.
A11: 2 LOG
A12: # | B12: Date | C12: Meeting | D12: Target | E12: Outcome | F12: What was decided or reported | G12: Follow-up action | H12: Owner (role) | I12: Due | J12: Status
A13: 1 | B13: 2026-09-24 | C13: MC meeting | D13: T1 | E13: Confirmed | F13: EXAMPLE ROW - delete before use. Automation backlog and per-item timeline accepted; asked that the two largest groups be surveyed first. | G13: Survey ESG and LSG duties before starting build | H13: Coordinator | I13: 2026-10-15 | J13: Done
A14: 2
A15: 3
A16: 4
A17: 5
A18: 6
A19: 7
A20: 8
A21: 9
A22: 10
A23: 11
A24: 12
A25: 13
... A43: 31
