Workbook

Sheet Note

Sheet Executive Summary
A1: AXC TEAM - OBJECTIVES AND ACTION PLAN
A2: FY2026-27 | 12-month plan built from the AI Transformation job description | Q1 = M1-M3, Q2 = M4-M6, Q3 = M7-M9, Q4 = M10-M12
A4: Start month (M1) | C4: 46296 | D4: Assumption. Change it and every Due date updates.
A6: 1 AXC OVERVIEW
A7: Team | C7: AI Transformation Team (AXC) – AXC Lead, AI Specialist, Coordinator
A8: What we are here to do | C8: AXC drives AI transformation across the company: sets the AI strategy and roadmap, redesigns work with AI, chooses the right tools, builds people's AI skills, measures AI maturity and impact, and keeps AI use safe. We are judged on real use and measured results, not on documents delivered.
A10: 2 OBJECTIVES & PROGRESS
A11: ID | B11: Objective | C11: Description | D11: Owner | E11: Done | F11: Progress | G11: Status
A12: O1 | B12: Strategy & Roadmap | C12: A company-wide AI strategy and roadmap tied to business priorities, reviewed every quarter by leadership. | D12: AXC Lead + Coordinator | E12: ='O1 Strategy'!$D$21&" of "&COUNTA('O1 Strategy'!$B$10:$B$20) -> 0 of 7 | F12: ='O1 Strategy'!$H$21 -> 0 | G12: =IF('O1 Strategy'!$G$2="","Not started",'O1 Strategy'!$G$2) -> Not started
A13: O2 | B13: Process Change | C13: Redesign the main workflows (coding, code review, testing, documentation, requirements, PM, reporting, communication) in the order set by the BOD, pilot them in real projects, and make the ones that work a standard for the whole company. | D13: AI Specialist + Coordinator + AXC Lead | E13: ='O2 Process'!$D$37&" of "&COUNTA('O2 Process'!$B$10:$B$36) -> 0 of 21 | F13: ='O2 Process'!$H$37 -> 0 | G13: =IF('O2 Process'!$G$2="","Not started",'O2 Process'!$G$2) -> Not started
A14: O3 | B14: Tools & Licenses | C14: Evaluate external tools on 6 criteria: applicability, productivity, user experience, cost, security and data protection. Run proof-of-value trials (PoV) and set the tools and usage for each role. Manage licenses, usage and cost. Consider internal AI infrastructure only when there is a clear reason. | D14: AI Specialist + Coordinator | E14: ='O3 Tools'!$D$30&" of "&COUNTA('O3 Tools'!$B$10:$B$29) -> 0 of 15 | F14: ='O3 Tools'!$H$30 -> 0 | G14: =IF('O3 Tools'!$G$2="","Not started",'O3 Tools'!$G$2) -> Not started
A15: O4 | B15: People & Skills | C15: A role-based AI capability program: skills, learning paths, hands-on training and best-practice sharing. Follow up on AI use after training, not stop at one course. | D15: Coordinator + AI Specialist | E15: ='O4 People'!$D$29&" of "&COUNTA('O4 People'!$B$10:$B$28) -> 0 of 14 | F15: ='O4 People'!$H$29 -> 0 | G15: =IF('O4 People'!$G$2="","Not started",'O4 People'!$G$2) -> Not started
A16: O5 | B16: Measurement & AML | C16: Measure AI maturity level (AML) objectively at 3 levels: individual, team and company. Find weak areas and act on them. Analyse the link between AI use and business results, and provide the numbers for the quarterly review. | D16: AXC Lead + Coordinator | E16: ='O5 Measurement'!$D$27&" of "&COUNTA('O5 Measurement'!$B$10:$B$26) -> 0 of 12 | F16: ='O5 Measurement'!$H$27 -> 0 | G16: =IF('O5 Measurement'!$G$2="","Not started",'O5 Measurement'!$G$2) -> Not started
A17: O6 | B17: Safety & Governance | C17: Set principles and a policy for responsible AI use: security, personal data, IP and client confidentiality. Keep a list of approved tools and permitted use. Work with Security, IT, HR, Legal and function leaders. | D17: AXC Lead + AI Specialist + Coordinator | E17: ='O6 Governance'!$D$30&" of "&COUNTA('O6 Governance'!$B$10:$B$29) -> 0 of 15 | F17: ='O6 Governance'!$H$30 -> 0 | G17: =IF('O6 Governance'!$G$2="","Not started",'O6 Governance'!$G$2) -> Not started
B18: TOTAL | E18: =('O1 Strategy'!$D$21+'O2 Process'!$D$37+'O3 Tools'!$D$30+'O4 People'!$D$29+'O5 Measurement'!$D$27+'O6 Governance'!$D$30)&" of "&(COUNTA('O1 Strategy'!$B$10:$B$20)+COUNTA('O2 Process'!$B$10:$B$36)+COUNTA('O3 Tools'!$B$10:$B$29)+COUNTA('O4 People'!$B$10:$B$28)+COUNTA('O5 Measurement'!$B$10:$B$26)+COUNTA('O6 Governance'!$B$10:$B$29)) -> 0 of 84 | F18: =IFERROR((SUM('O1 Strategy'!$H$10:$H$20)+SUM('O2 Process'!$H$10:$H$36)+SUM('O3 Tools'!$H$10:$H$29)+SUM('O4 People'!$H$10:$H$28)+SUM('O5 Measurement'!$H$10:$H$26)+SUM('O6 Governance'!$H$10:$H$29))/(COUNTA('O1 Strategy'!$B$10:$B$20)+COUNTA('O2 Process'!$B$10:$B$36)+COUNTA('O3 Tools'!$B$10:$B$29)+COUNTA('O4 People'!$B$10:$B$28)+COUNTA('O5 Measurement'!$B$10:$B$26)+COUNTA('O6 Governance'!$B$10:$B$29)),0) -> 0
A20: 3 HOW THIS PLAN WORKS
A21: - | B21: Six objectives (O1-O6), each answering one question. Each objective has its own sheet with its details and actions.
A22: - | B22: Each objective detail has a goal, the conditions it needs first, and a list of actions with owner and due month.
A23: - | B23: Due dates are counted from the Start month above (M1). 'ongoing' actions repeat (monthly, quarterly, per pilot …).
A24: - | B24: Each action has a Status and a % (0-100%) filled by its owner. Progress = average % of all actions (empty = 0%). Done = number of actions marked Done.
A25: - | B25: No numeric targets yet: they are set after the first baseline is measured (O5).
A26: - | B26: Planned workflow order is Engineering → Delivery → Management. If the BOD picks a different first pilot, the order changes.
A27: - | B27: BOD sessions: M2 (strategy, workflow order, first pilot, decision table, review schedule, trial license budget) · M3 (AI Usage Policy) · M5 (AML framework) · then the quarterly reviews.
A29: 4 HOW TO USE THIS FILE
A30: 1 | B30: Owners fill in only the yellow cells on their objective sheet: Status of each action, Reference document, Note, and the objective Status at the top.
A31: 2 | B31: This summary updates itself from the objective sheets. Do not type into it (except the Start month).
A32: 3 | B32: To add an action, use the spare rows at the end of each action table.
A33: 4 | B33: Update statuses monthly; review fully at each quarterly review.
A34: 5 | B34: Record every approval, confirmation and report from a meeting in the Meeting Log sheet.
A36: 5 DOCUMENT CONTROL
A37: Version | C37: 4.2 (01/10/2026)
A38: Period | C38: FY2026-27 (12 months from the Start month)
A39: Based on | C39: AXC_AI_Transformation_Objectives_BOD.xlsx
A40: Previous version | C40: v2.4 saved as [AXC] AXC_Team_Objectives_ActionPlan_FY2026-2027_v2.4_backup.xlsx
A41: Prepared by | C41: AXC Team
A42: Last updated | C42: 01/10/2026
A43: Changes | C43: workshop removed (1.1); use-case list moved to O2 as 2.1; quarterly review dates set by the BOD; 6-month reviews replaced by BOD confirmation; actions written without references to other items; pilots and baselines moved into each workflow (2.2-2.4); approved tool list kept only in 3.1; trial licenses for PoV added; AI Champion item removed (AI leads act as power users); O4: earlier skills draft, basic course = first step of learning path, role content owned by AI Specialist, new-hire onboarding added; O5: rules for individual AML results, cycle 1 team/company only; O6: personal-data law in data classes, shadow-AI check, tool list needed before policy approval; final review: first pilot and trial budget dated at BOD sessions, Q1 workload rebalanced, plain-English terms; v4.1: use-case list removed – the BOD sets the workflow order and first pilot, each workflow starts with the function head confirming the use case, owner and AI lead; v4.2: % column added (Progress = average %), Note column filled with work already done, mapped from the MC reports and AXC documents (each note cites its source; "Input:" = useful input, the action itself not started).

Sheet O1 Strategy
A1: O1 - Strategy & Roadmap
A2: Owner | C2: AXC Lead + Coordinator | F2: Status | G2: Not started
A3: Where are we going, and are we on track?
A5: 1 OBJECTIVE
A6: A company-wide AI strategy and roadmap tied to business priorities, reviewed every quarter by leadership.
A8: 2 ACTION PLAN
A9: # | B9: Quarter | C9: Action | D9: Owner | E9: Partners | F9: Due | G9: Status | H9: % | I9: Reference document | J9: Note
A10: 1.1 | C10: AI strategy & roadmap approved | D10: Goal: One company AI strategy and 12-month roadmap, approved by the BOD, that all functions follow. Needs first: BOD names a sponsor; Company business priorities for the year are available JD: 1.1, 1.2
A11: 1 | B11: Q1 | C11: Collect business priorities from the BOD, with input from function heads | D11: AXC Lead | E11: BOD sponsor | F11: =EDATE('Executive Summary'!$C$4,0) -> 46296 | G11: Not started | J11: Input: Function-level input has started. AI PICs were named per BU (LSG 2, ESG 1) to gather BU needs, with ESG and LSG set as first priorities. MC leadership asked for KPI + timeline for ~10 management items, 1-2 items done and user-tested each month, and 100+ items at operation level. Earlier, the BOD asked to raise the 2026 efficiency-gain target from 25% to 30%. No BOD priority collection is recorded yet. Source: AXC MC 07/08/2026 p10; AXC MC 28/08/2026 p2; MoM AXC MC 28/08/2026 s2; SSC MC 06/02/2026 p2, p4 (25% in SSC MC 22/01/2026 p4).
A12: 2 | B12: Q1 | C12: Write strategy + roadmap | D12: AXC Lead | E12: BOD sponsor | F12: =EDATE('Executive Summary'!$C$4,1) -> 46327 | G12: In progress | I12: [AXC] AXC_Team_Objectives_ActionPlan_FY2026-2027.xlsx; AXC_AI_Transformation_Objectives_BOD.xlsx; AXC_AI_Transformation_Objectives.pptx | J12: Roadmap + objectives drafted (01/10/2026). 1-page strategy (business problems, yearly goals) pending business priorities from action 1. Input: An earlier AI Adoption Road Map exists, running from Q1.26 Pilot (Done) to Q3-4.27 Scale & AI-First and mapped to Levels 1-6. The undated AX BOD briefing frames 3 steps (Step 1 'Use the tools' Done with 214 AI accounts issued, Step 2 partly in progress, Step 3 not started) and 2 conditions (people, AI data-access policy). The MC chose Google Workspace automation first, with no internal or open-source infrastructure yet. No strategy + roadmap document has been written yet. Source: SSC MC 16/04/2026 p5; AX_BOD_Briefing_EN slides 1-2; MoM AXC MC 28/08/2026 Decisions #7, #9.
A13: 3 | B13: Q1 | C13: BOD sets the priorities, the order of the workflow areas and the first pilot with its pilot project, and approves the strategy + roadmap, in one BOD session with the AI principles, decision table and trial license budget | D13: AXC Lead | E13: BOD sponsor | F13: =EDATE('Executive Summary'!$C$4,1) -> 46327 | G13: Not started | J13: Input for the trial license budget: a TO-BE account process was proposed, with probation use paid by AXC and the BOD deciding from AXC's real usage summary (proposal only). The MC agreed more accounts can be funded based on AML results. No BOD session, pilot choice or budget approval is recorded. Source: AXC MC 03/07/2026 p7; MoM AXC MC 28/08/2026 Decision #11.
A14: 1.2 | C14: Quarterly transformation review | D14: Goal: A quarterly review where leaders use one report to decide to continue, scale or stop each initiative. Needs first: BOD confirms the review schedule; Usage, cost, AML and pilot results as they become available JD: 1.5, 5.5
A15: 4 | B15: Q1 | C15: BOD confirms the quarterly review schedule, in the same BOD session as the strategy approval | D15: AXC Lead | E15: BOD, function heads | F15: =EDATE('Executive Summary'!$C$4,1) -> 46327 | G15: Not started
A16: 5 | B16: Q1 | C16: 1-page report template | D16: Coordinator | E16: BOD, function heads | F16: =EDATE('Executive Summary'!$C$4,2) -> 46357 | G16: Not started
A17: 6 | B17: ongoing | C17: Functions can propose new use cases before each quarterly review; the BOD decides | D17: AXC Lead | E17: BOD, function heads | F17: Quarterly | G17: Not started | J17: Input: An informal channel exists. AXC engaged AI-interested PICs per BU (LSG 2, ESG 1) to surface BU-specific AI use cases, and the work continues with ESG and LSG. This is not yet a quarterly mechanism with BOD decisions. Source: AXC MC 07/08/2026 p10; AXC MC 28/08/2026 p2.
A18: 7 | B18: ongoing | C18: Quarterly review: the BOD reviews the report and confirms continue / scale / stop and roadmap updates | D18: AXC Lead | E18: BOD, function heads | F18: Per BOD schedule | G18: Not started
A21: ACTIONS DONE | D21: =COUNTIF($G$11:$G$20,"Done") -> 0 | E21: ="of "&(COUNTA($B$11:$B$20))&" actions" -> of 7 actions | G21: Progress | H21: =IFERROR(SUM($H$11:$H$20)/(COUNTA($B$11:$B$20)),0) -> 0

Sheet O2 Process
A1: O2 - Process Change
A2: Owner | C2: AI Specialist + Coordinator + AXC Lead | F2: Status | G2: Not started
A3: How does the work change?
A5: 1 OBJECTIVE
A6: Redesign the main workflows (coding, code review, testing, documentation, requirements, PM, reporting, communication) in the order set by the BOD, pilot them in real projects, and make the ones that work a standard for the whole company.
A8: 2 ACTION PLAN
A9: # | B9: Quarter | C9: Action | D9: Owner | E9: Partners | F9: Due | G9: Status | H9: % | I9: Reference document | J9: Note
A10: 2.1 | C10: Engineering workflows redesigned: coding, code review | D10: Goal: A new AI way of working for coding and code review, with clear rules for human review of AI code, ready for pilot. Needs first: BOD confirms the first pilot and its pilot project; Approved tool list and AI Usage Policy in place; The pilot project's client allows AI use; Pilot team has taken Safe AI training; AI incident channel is ready JD: 1.2, 1.3, 2.1, 2.2, 4.5
A11: 1 | B11: Q1 | C11: Function head confirms the use case and the pilot project, and names the owner and AI lead | D11: AXC Lead | E11: Engineering lead | F11: =EDATE('Executive Summary'!$C$4,2) -> 46357 | G11: Not started | J11: Input: these candidate engineering pilots already use AI: TMS (GitHub Copilot, 6 accounts), BluePrint (Copilot 22%, then a Cursor pilot), HRX (Claude Agent Teams PoC) and HRM-Sambu (Cursor + Claude). No function head has confirmed a use case, pilot project, owner or AI lead under the new plan. Source: SSC MC 16/10/2025 p5; SSC MC 27/02/2026 p6; SSC MC 12/03/2026 p7; SSC MC 22/05/2026 p11.
A12: 2 | B12: Q1 | C12: Map the current way of working in the pilot project | D12: AI Specialist | E12: Engineering lead | F12: =EDATE('Executive Summary'!$C$4,2) -> 46357 | G12: Not started | J12: Input: the AML self-assessments describe today's engineering work. BluePrint: 'Review is fully manual', 'AI is used to draft, not to work'. CARIS: AI does the work but the checks are all manual. LSG: Claude is used by all roles, but only Dev has a skill library; the step 'AXC analyzes current project workflow' is planned, not done, and no pilot project is confirmed. Source: AXC MC 24/07/2026 slides 8-9; AXC MC 28/08/2026 p6, p10.
A13: 3 | B13: Q1 | C13: Measure the baseline: time per task, review time, defects found | D13: AI Specialist | E13: Engineering lead | F13: =EDATE('Executive Summary'!$C$4,2) -> 46357 | G13: Not started | J13: Input: the only past figures are coding gains self-reported by projects, with no method shown. They are TMS Copilot 5% to 22% (Wk1-2 to Wk7-8, coding scope only), 5 projects at 30-35% (avg 31%), BluePrint ~20% time saved per dev and HRM-Sambu ~35-40%. HRX PoC: senior 50%, fresher 20%, shown as 'AVERAGE 35.5%' (the simple mean is 35%), measured against a no-AI estimate. These conflict with lower earlier figures (e.g. Copilot 22%, CARIS 20% on 27/02), and none measures time per task, review time or defects. Source: SSC MC 10/12/2025 p5; SSC MC 16/04/2026 p14; SSC MC 22/05/2026 p11; SSC MC 12/03/2026 p7; SSC MC 27/02/2026 p6.
A14: 4 | B14: Q2 | C14: Design the new workflow, review rules and standard prompts | D14: AI Specialist | E14: Engineering lead | F14: =EDATE('Executive Summary'!$C$4,3) -> 46388 | G14: Not started | J14: Input: the AML found Control (review of AI output) below Required in all 3 projects, a company-wide gap; the proposed fix is to 'bring AI into the review step, not just the coding step'. Building blocks: a generic with/without-AI process including a Code Review step ('Review AI pre-check → verify logic → approve'), the Prompting Hub (roadmap 20% complete on 27/02; v1 in internal testing on 16/04) and the idea of standard Rules.md/Pattern.md files. Source: AXC MC 28/08/2026 p8-11; SSC MC 22/05/2026 p7; SSC MC 27/02/2026 p7; SSC MC 16/04/2026 p5; SSC MC 12/03/2026 p8.
A15: 5 | B15: Q2 | C15: Run the pilot in the pilot project and measure before/after | D15: AI Specialist | E15: Engineering lead | F15: =EDATE('Executive Summary'!$C$4,5) -> 46447 | G15: Not started | J15: Input: an earlier coding pilot ran on TMS with GitHub Copilot (6 accounts received 14-Oct-2025, 6/6 active by 30/10). SSC self-reported a gain of 5% (Wk1-2) rising to 22% (Wk7-8, 'TARGET ACHIEVED'), coding scope only, with no baseline or method shown, and no final report appears in the files. Source: SSC MC 16/10/2025 p5; SSC MC 30/10/2025 p5; SSC MC 10/12/2025 p5.
A16: 6 | B16: Q2 | C16: Adjust the workflow after the pilot | D16: AI Specialist | E16: Engineering lead | F16: =EDATE('Executive Summary'!$C$4,5) -> 46447 | G16: Not started
A17: 2.2 | C17: Delivery workflows redesigned: requirements, testing, documentation | D17: Goal: A new AI way of working for requirements, testing and documentation, with a quality check on AI output, ready for pilot. Needs first: BOD has set the order of the workflow areas; Approved tool list and AI Usage Policy in place; The pilot project's client allows AI use; Pilot team has taken Safe AI training; AI incident channel is ready; Current document and test templates are used as baseline JD: 1.2, 1.3, 2.1, 2.2, 4.5
A18: 7 | B18: Q2 | C18: Function head confirms the use case and the pilot project, and names the owner and AI lead | D18: AXC Lead | E18: BA lead, QA lead | F18: =EDATE('Executive Summary'!$C$4,4) -> 46419 | G18: Not started | J18: Input: AI PICs are named (LSG 2, ESG 1), and AXC is working with the ERP projects (CLT Office, Fine Chemical) on BA/spec work. The LSG plan is for AXC to build common AI skills for BA & QC first, then run a PoC in a small team, but no function head has confirmed a use case, pilot project, owner or AI lead. Source: AXC MC 07/08/2026 p6-10; AXC MC 28/08/2026 p6.
A19: 8 | B19: Q2 | C19: Map the current way of working for BA and QA | D19: AI Specialist | E19: BA lead, QA lead | F19: =EDATE('Executive Summary'!$C$4,4) -> 46419 | G19: In progress | J19: Partial current-state map for 2 ERP projects (not a confirmed pilot). CLT Office: 2.0 BA / 11.0 Dev, specs not released on time, BA use limited by gaps in legacy and accounting knowledge, QC tests and retests by hand. Fine Chemical: 3.0 BA / 5.0 Dev, specs conflict, AI used in all 8 steps (BA, Dev, QA). In both, delays come from the written spec, AI is still a helper and no written process requires it. Source: AXC MC 07/08/2026 p7; AXC MC 28/08/2026 p5; AI_Adoption_Summary_2Projects slide 1.
A20: 9 | B20: Q2 | C20: Measure the baseline: time to write requirements, test cases and documents; rework | D20: AI Specialist | E20: BA lead, QA lead | F20: =EDATE('Executive Summary'!$C$4,5) -> 46447 | G20: Not started | J20: Input: Fine-Chemical reports 'Documents 2.2× faster, screens 3× faster' (project-reported; method and comparison not shown). QC test cases from User Story + Figma: Gemini 16, ChatGPT 49, Claude 71, with 'coverage improved by 40–65%' (calculation not shown). Neither is a baseline for time to write requirements, test cases or documents, or for rework. Source: AXC MC 28/08/2026 p5; SSC MC 12/03/2026 p10; SSC MC 22/05/2026 p6.
A21: 10 | B21: Q3 | C21: Design the new workflow with a check step for AI output | D21: AI Specialist | E21: BA lead, QA lead | F21: =EDATE('Executive Summary'!$C$4,6) -> 46478 | G21: In progress | J21: A first BA workflow kit with check steps exists for ERP Fine-Chemical: a shared Claude Project with BA-SPEC-KIT v0.1 (2026-08-04), URD/screen templates, a QA gate file (06_biz__qa-room-gate) and 4 skills created 8/5/26 (biz-sync, check-consistency, gen-urd, prep-meeting). AXC has proposed a process where 'AI is a step, not a helper', with people approving and an AI check built in, but it has not been run as a measured pilot. Source: AXC MC 07/08/2026 p8-9; AI_Adoption_Summary_2Projects slide 1.
A22: 11 | B22: Q3 | C22: Run the pilot in the pilot project and measure before/after | D22: AI Specialist | E22: BA lead, QA lead | F22: =EDATE('Executive Summary'!$C$4,8) -> 46539 | G22: Not started
A23: 12 | B23: Q4 | C23: Adjust the workflow after the pilot | D23: AI Specialist | E23: BA lead, QA lead | F23: =EDATE('Executive Summary'!$C$4,11) -> 46631 | G23: Not started
A24: 2.3 | C24: Management workflows redesigned: PM, reporting, communication | D24: Goal: A new AI way of working for project management, reporting and communication, ready for pilot. Needs first: BOD has set the order of the workflow areas; Approved tool list and AI Usage Policy in place; The pilot project's client allows AI use; Pilot team has taken Safe AI training; AI incident channel is ready; Current report and minutes templates are available JD: 1.2, 1.3, 2.1, 2.2, 4.5
A25: 13 | B25: Q2 | C25: Function head confirms the use case and the pilot project, and names the owner and AI lead | D25: AXC Lead | E25: PMO, Corporate heads, AI Specialist | F25: =EDATE('Executive Summary'!$C$4,4) -> 46419 | G25: Not started | J25: Input: one possible management use case is a Jira email > Google Chat > central Google Sheet flow (demoed at MC). The GSD team is still in an 'Active evaluation & process integration phase' for the Jira workflow, so real use is not confirmed, and no function head has confirmed a pilot, owner or AI lead. Source: MoM AXC MC 28/08/2026 s3.4 (Gemini auto-transcript); AXC MC 28/08/2026 p4.
A26: 14 | B26: Q2 | C26: Map the current way of working | D26: Coordinator | E26: PMO, Corporate heads, AI Specialist | F26: =EDATE('Executive Summary'!$C$4,5) -> 46447 | G26: Not started
A27: 15 | B27: Q2 | C27: Measure the baseline: time spent on plans, reports and minutes | D27: Coordinator | E27: PMO, Corporate heads, AI Specialist | F27: =EDATE('Executive Summary'!$C$4,5) -> 46447 | G27: Not started
A28: 16 | B28: Q3 | C28: Design the new workflow | D28: Coordinator | E28: PMO, Corporate heads, AI Specialist | F28: =EDATE('Executive Summary'!$C$4,8) -> 46539 | G28: Not started | J28: Input: automation templates for management tasks are available to build on: 'Ticket → weekly report', 'Stale ticket reminder' and 'New ticket → AI triage → notify' (BluePrint + n8n), part of 10 BluePrint flows shared on 24/07. None is a designed workflow for a confirmed management pilot. Source: AXC MC 24/07/2026 slide 7.
A29: 17 | B29: Q4 | C29: Run the pilot and measure before/after | D29: Coordinator | E29: PMO, Corporate heads, AI Specialist | F29: =EDATE('Executive Summary'!$C$4,11) -> 46631 | G29: Not started
A30: 18 | B30: Q4 | C30: Adjust the workflow after the pilot | D30: Coordinator | E30: PMO, Corporate heads, AI Specialist | F30: =EDATE('Executive Summary'!$C$4,11) -> 46631 | G30: Not started
A31: 2.4 | C31: Proven workflows become company standards | D31: Goal: Every new workflow is tested in a real project with measured results; the ones that work become company standards. Needs first: A pilot has met its go/no-go target; The function head agrees to own the standard JD: 2.3, 2.4, 2.5
A32: 19 | B32: Q1 | C32: Pilot template: scope and go/no-go rules, using the metrics from the impact measurement method | D32: AI Specialist | E32: PMO/QA, function heads | F32: =EDATE('Executive Summary'!$C$4,1) -> 46327 | G32: Not started | J32: Input: earlier pieces to reuse are the HRX PoC method (take a new user story and compare actual effort with agentic AI against a no-AI estimate, senior vs fresher) and the 3-step rollouts: Select & adjust (wk 1-2), Pilot & refine (wk 3-4), Stabilise & measure; and Share & improve, Start & measure, Improve & act. None defines scope or go/no-go rules. Source: SSC MC 12/03/2026 p7; AXC MC 03/07/2026 p8-9.
A33: 20 | B33: ongoing | C33: Package an SOP after each successful pilot | D33: AI Specialist | E33: PMO/QA, function heads | F33: Per pilot | G33: Not started
A34: 21 | B34: ongoing | C34: Review and update standard workflows, confirmed by the BOD at the quarterly review | D34: AI Specialist | E34: PMO/QA, function heads | F34: Per BOD review | G34: Not started
A37: ACTIONS DONE | D37: =COUNTIF($G$11:$G$36,"Done") -> 0 | E37: ="of "&(COUNTA($B$11:$B$36))&" actions" -> of 21 actions | G37: Progress | H37: =IFERROR(SUM($H$11:$H$36)/(COUNTA($B$11:$B$36)),0) -> 0

Sheet O3 Tools
A1: O3 - Tools & Licenses
A2: Owner | C2: AI Specialist + Coordinator | F2: Status | G2: Not started
A3: Which tools do we use, and at what cost?
A5: 1 OBJECTIVE
A6: Evaluate external tools on 6 criteria: applicability, productivity, user experience, cost, security and data protection. Run proof-of-value trials (PoV) and set the tools and usage for each role. Manage licenses, usage and cost. Consider internal AI infrastructure only when there is a clear reason.
A8: 2 ACTION PLAN
A9: # | B9: Quarter | C9: Action | D9: Owner | E9: Partners | F9: Due | G9: Status | H9: % | I9: Reference document | J9: Note
A10: 3.1 | C10: One tool evaluation process | D10: Goal: One process to check every AI tool on 6 criteria, including security, before it is used or bought. Needs first: Security names a reviewer for the security criteria; Data categories defined in the AI Usage Policy; BOD confirms a budget for trial licenses JD: 3.1, 3.2, 3.3, 3.5
A11: 1 | B11: Q1 | C11: 6-criteria scorecard | D11: AI Specialist | E11: Security, IT | F11: =EDATE('Executive Summary'!$C$4,0) -> 46296 | G11: Not started | J11: Input: earlier tool evaluations exist, none on a 6-criteria scorecard: radar scoring of Cursor/Claude/Copilot on 13 areas and 3 roles (12/03/2026), AI Tools Comparison Report v1 (Claude, Cursor, Copilot, ChatGPT, Gemini across 4 project types and 3 roles), and a Cursor Individual vs Business comparison that includes security & policy controls. Source: SSC MC 12/03/2026 p13; SSC MC 22/05/2026 p6; SSC MC 22/01/2026 p6.
A12: 2 | B12: Q1 | C12: Score tools already in use; passing tools go on the approved tool list | D12: AI Specialist | E12: Security, IT | F12: =EDATE('Executive Summary'!$C$4,1) -> 46327 | G12: Not started | J12: Input: tools in use total 180 accounts (Claude 61, GitHub 55, Cursor 41, Claude Max 15, ChatGPT 8). Earlier reviews recommend 'Claude + Cursor', and draft standard AXC-STD-AI-001 v0.9 (17/09/2026, awaiting approval) sets ChatGPT + Claude as the standard platform and leaves Gemini out until the Google Workspace tier is upgraded (R5.5). No tool has been scored yet and there is no approved list. Source: AXC MC 28/08/2026 p7; SSC MC 12/03/2026 p13; SSC MC 22/05/2026 p6; AI_Cost_Quota_Standard_by_Role.md §5, R5.5.
A13: 3 | B13: Q1 | C13: Get trial licenses for proof-of-value (PoV) tools, after the BOD confirms the budget | D13: AI Specialist | E13: Security, IT | F13: =EDATE('Executive Summary'!$C$4,2) -> 46357 | G13: Not started | J13: Input: the 03/07 request-process proposal (option 2) has trial ('probation') use paid by AXC, after which the BOD decides on real usage data; no approval is recorded. Similar request: a 3-month OpenAI API pilot for HR CV screening (Oct-Dec 2026, 5-20 $/month, 20 $/month hard limit). The MoM of 28/08 had proposed 20-50 USD/month, still awaiting approval. Source: AXC MC 03/07/2026 p7; AXC_Ticket_AI_API_Budget_CV_Screening.md (18/09/2026); MoM AXC MC 28/08/2026 s3.2, Decision #12.
A14: 4 | B14: Q2 | C14: Keep a watch list of new tools, updated every quarter | D14: AI Specialist | E14: Security, IT | F14: =EDATE('Executive Summary'!$C$4,3) -> 46388 | G14: Not started | J14: Starts this month, then ongoing. Input: 'Keep up to date with AI tools/features in market' was a standing next action. The 12/03 deck notes that tool rankings change fast: Cursor was rated above Claude about three months earlier. n8n was reviewed as a new tool on 30/10/2025. There is no formal watch list with quarterly updates. Source: SSC MC 16/04/2026 p2; SSC MC 12/03/2026 p13; SSC MC 30/10/2025 p7.
A15: 5 | B15: Q2 | C15: Trial new tools on real work inside workflow pilots (PoV); each tool must pass the security criteria first | D15: AI Specialist | E15: Security, IT | F15: =EDATE('Executive Summary'!$C$4,5) -> 46447 | G15: Not started | J15: Input: earlier hands-on trials on real work can serve as references: Claude Agent Teams PoC on HRX (avg 35.5% on one user story; needs a Max account, $100-200), Copilot in TMS (5% to 22% over 8 weeks), and QC test-case generation (Claude 71, ChatGPT 49, Gemini 16). None went through a security check first. Source: SSC MC 27/02/2026 p4-5; SSC MC 12/03/2026 p5-8, p10; SSC MC 22/05/2026 p6; SSC MC 16/10/2025-10/12/2025.
A16: 6 | B16: Q3 | C16: Criteria for internal AI infrastructure | D16: AI Specialist | E16: Security, IT | F16: =EDATE('Executive Summary'!$C$4,8) -> 46539 | G16: Not started | J16: Input: AIC researched local AI: RAG ~2-3 weeks to demo, fine-tuning ~1 month, minimum GPU >= 48GB VRAM, RAM >= 64GB and ~3 headcounts. The work was paused for 'lacking some information', and on 28/08 the MC decided not to invest in internal or open-source infrastructure for now (Decision #7). Source: SSC MC 22/05/2026 p5; SSC MC 16/04/2026 p7-12; MoM AXC MC 28/08/2026 s6, Decision #7.
A17: 3.2 | C17: Tool & license standard by role | D17: Goal: A standard that sets which tools and licenses each role gets, and what they are used for. Needs first: Tool scoring and trial (PoV) results; Tool budget confirmed by the BOD JD: 3.3, 3.4
A18: 7 | B18: Q2 | C18: List roles and tool needs | D18: Coordinator | E18: IT, Finance | F18: =EDATE('Executive Summary'!$C$4,3) -> 46388 | G18: In progress | J18: Draft standard AXC-STD-AI-001 v0.9 (17/09/2026, awaiting approval) lists 3 role groups (A PM/Leader/Manager; B Dev/Tech Lead/DevOps/AI Engineer/QC automation; C BC/BA/Designer/QC/Technical Writer) x 3 tiers, each with a default tool set: A $20/$30/$60, B $45/$150/$250, C $20/$60/$120 per person per month. This follows MoM Action #5 (Kamu: account allocation policy by role/purpose). Source: AI_Cost_Quota_Standard_by_Role.md §2-§5; MoM AXC MC 28/08/2026 s6, Action #5.
A19: 8 | B19: Q3 | C19: Final standard after the PoV trials; budget confirmed by the BOD at the quarterly review | D19: Coordinator | E19: IT, Finance | F19: =EDATE('Executive Summary'!$C$4,6) -> 46478 | G19: In progress | J19: A draft standard exists (v0.9, 17/09/2026), with a price reference table verified 17/09/2026 and a quarterly review clause (R3.5). The PoV trials and the BOD budget confirmation have not happened. MC direction (28/08): AI cost may rise while labor cost falls, keeping total cost flat, and more accounts can be funded based on AML results (Decision #11). Source: AI_Cost_Quota_Standard_by_Role.md header, R3.5, §8; MoM AXC MC 28/08/2026 s6, Decision #11.
A20: 9 | B20: Q3 | C20: Apply to all licenses | D20: Coordinator | E20: IT, Finance | F20: =EDATE('Executive Summary'!$C$4,8) -> 46539 | G20: Not started
A21: 10 | B21: ongoing | C21: Review and update the standard, confirmed by the BOD at the quarterly review | D21: Coordinator | E21: IT, Finance | F21: Per BOD review | G21: Not started | J21: Input: draft standard v0.9 already requires a quarterly review (R3.5: default tier reviewed using upgrade-approval rate, share of staff hitting the Tier 1 cap, and AML results), plus a mandatory quarterly price-table update. The standard is not approved yet. Source: AI_Cost_Quota_Standard_by_Role.md header, R3.5, §8.
A22: 3.3 | C22: Usage & cost tracked monthly | D22: Goal: Every AI license tracked each month for usage and cost, with unused licenses taken back. Needs first: IT gives access to tool admin data; Finance provides cost and renewal dates JD: 3.4, 6.4
A23: 11 | B23: Q1 | C23: License register | D23: Coordinator | E23: IT, Finance | F23: =EDATE('Executive Summary'!$C$4,0) -> 46296 | G23: In progress | J23: Accounts counted: 180 AI accounts by division (New Business 131, CLT Service 36, Management Support 7, BOD 6) and by type (Claude 61, GitHub 55, Cursor 41, Claude Max 15, ChatGPT 8), with a monthly trend from 37 (02/26) to 180 (07/26). There is no per-license register yet (holder, cost, dates). Conflicts to reconcile: the BOD briefing says 214 accounts issued (deck undated, file saved 29/09/2026), and 03/07 p5 gives 97/120/134 for 04-06/26 against 87/102/141 on 28/08. Source: AXC MC 28/08/2026 p7; AX_BOD_Briefing_EN slide 1; AXC MC 03/07/2026 p5.
A24: 12 | B24: Q1 | C24: First monthly usage and cost report | D24: Coordinator | E24: IT, Finance | F24: =EDATE('Executive Summary'!$C$4,1) -> 46327 | G24: In progress | J24: Cost data reported to MC: 18 to 134 accounts and $290 to $3,580/month (25/12-26/06), avg $30/account, Dec 2026 forecast base ~175 users / $4.7K, growth ~250 / $7K. A usage survey (May-Jul 2026) covered 46 accounts (19 non-dev, 27 dev), and the OmniRoute monitoring tool is 'Usage Monitoring (50% Done)'. No cost figure has been reported since 03/07, and no monthly report has been issued yet. Source: AXC MC 03/07/2026 p5; AXC MC 24/07/2026 slides 4, 6; AXC MC 28/08/2026 p7.
A25: 13 | B25: Q1 | C25: Take-back rules + alert limits | D25: Coordinator | E25: IT, Finance | F25: =EDATE('Executive Summary'!$C$4,1) -> 46327 | G25: In progress | J25: A 5-step usage review was proposed (weekly snapshot, flag low usage, propose, PIC confirms, AXC monitors), and one take-back was done: 11 Cursor + 1 Claude accounts reallocated from low-use holders to ESG. Draft standard v0.9 requires an org-level hard spending limit before allocation (R7.2) and a separate cap per agentic tool (R7.3). No formal take-back rule or alert thresholds are set yet. Source: AXC MC 24/07/2026 slide 5; AXC MC 28/08/2026 p7; AI_Cost_Quota_Standard_by_Role.md R7.2-R7.3.
A26: 14 | B26: ongoing | C26: Monthly usage and cost report | D26: Coordinator | E26: IT, Finance | F26: Monthly | G26: Not started | J26: Input: AI account status was reported at the MC meetings of 03/07, 24/07, 07/08 and 28/08 (not on a fixed monthly cycle; cost only on 03/07). OmniRoute, where users connect Claude Code, Copilot or Cursor accounts, is the planned data source and is 50% done. Source: AXC MC 03/07/2026 p5; AXC MC 24/07/2026 slide 6; AXC MC 07/08/2026 p11; AXC MC 28/08/2026 p7.
A27: 15 | B27: Q3 | C27: Add cost vs. impact to the monthly report, using pilot results | D27: Coordinator | E27: IT, Finance | F27: =EDATE('Executive Summary'!$C$4,6) -> 46478 | G27: Not started | J27: Starts this month, then ongoing. Input: draft standard v0.9 makes 'AI cost per unit of completed work' (per US, per screen, per test-case set) the mandatory metric instead of token count (R4.2). An earlier Cursor/Claude pilot projected ~$2,600 saving and ~$2,360 net (an estimate, not a measured result). Source: AI_Cost_Quota_Standard_by_Role.md R4.2; SSC MC 13/11/2025 p6.
A30: ACTIONS DONE | D30: =COUNTIF($G$11:$G$29,"Done") -> 0 | E30: ="of "&(COUNTA($B$11:$B$29))&" actions" -> of 15 actions | G30: Progress | H30: =IFERROR(SUM($H$11:$H$29)/(COUNTA($B$11:$B$29)),0) -> 0

Sheet O4 People
A1: O4 - People & Skills
A2: Owner | C2: Coordinator + AI Specialist | F2: Status | G2: Not started
A3: Are our people able to use AI?
A5: 1 OBJECTIVE
A6: A role-based AI capability program: skills, learning paths, hands-on training and best-practice sharing. Follow up on AI use after training, not stop at one course.
A8: 2 ACTION PLAN
A9: # | B9: Quarter | C9: Action | D9: Owner | E9: Partners | F9: Due | G9: Status | H9: % | I9: Reference document | J9: Note
A10: 4.1 | C10: Skills framework & learning path by role | D10: Goal: Clear AI skill levels and a learning path for every role. Needs first: HR co-owns this item; Role list from the tool & license standard; Levels match the AML levels JD: 4.1, 4.2
A11: 1 | B11: Q2 | C11: Draft skill levels, aligned with the AML levels | D11: Coordinator | E11: HR, function heads | F11: =EDATE('Executive Summary'!$C$4,3) -> 46388 | G11: In progress | J11: Started: AI certification levels drafted (C1 Foundation Basic, C2 Working Advanced, C3 role track Dev/BC/QC, C4 badge); by 08/05 C1 and C2 were 'In Review', C3 TBD and C4 still being researched, and on 22/05 2 of 4 levels were reported complete. They are not yet aligned with AML: AML has only a project-level 'AI Skill' axis, and on 28/08 the MC asked for individual AML used in hiring (e.g. AML level 3+). The v2.4 plan marks C1-C4 as 'defined/Done', but the MC reports show only 2/4 complete. Source: SSC MC 16/04/2026 p6; SSC MC 08/05/2026 p7; SSC MC 22/05/2026 p2; AXC MC 28/08/2026 p8-11; MoM AXC MC 28/08/2026 s5.
A12: 2 | B12: Q2 | C12: HR + function heads approve, after the AML framework is approved | D12: Coordinator | E12: HR, function heads | F12: =EDATE('Executive Summary'!$C$4,5) -> 46447 | G12: Not started
A13: 3 | B13: Q3 | C13: Add role parts when standard workflows exist | D13: AI Specialist | E13: HR, function heads, Coordinator | F13: =EDATE('Executive Summary'!$C$4,6) -> 46478 | G13: Not started | J13: Starts this month, then ongoing.
A14: 4 | B14: ongoing | C14: Update every year | D14: Coordinator | E14: HR, function heads | F14: Yearly | G14: Not started
A15: 4.2 | C15: Training that continues after the course | D15: Goal: A training program that people apply in their daily work, followed up for 90 days after each course. Needs first: HR has a schedule and sign-up channel; AI Usage Policy approved (for the Safe AI content) JD: 4.3, 4.6
A16: 5 | B16: Q1 | C16: Agree schedule, format and sign-up with HR | D16: Coordinator | E16: HR/L&D | F16: =EDATE('Executive Summary'!$C$4,1) -> 46327 | G16: In progress | J16: With L&D, AXC agreed on sharing format, delivery mode and material standards, and unified the document templates. As of 03/07, audience coverage, timeline and scheduling were still under review, no sign-up was recorded, and no later MC report updates this item. Source: AXC MC 03/07/2026 p10; SSC MC 22/05/2026 p2.
A17: 6 | B17: Q1 | C17: Safe AI training for the pilot team, after the AI Usage Policy is approved | D17: Coordinator | E17: HR/L&D | F17: =EDATE('Executive Summary'!$C$4,2) -> 46357 | G17: Not started
A18: 7 | B18: Q2 | C18: Safe AI + basic course company-wide; the basic course is the first step of the learning path | D18: Coordinator | E18: HR/L&D | F18: =EDATE('Executive Summary'!$C$4,5) -> 46447 | G18: In progress | J18: Basic course material is ready: 'AI Training Materials' was marked Done on 22/05 and C1 AI Foundation Basic was 'In Review' on 08/05. The question bank was still in progress, C1 delivery (planned for M6) is not recorded, and no Safe AI module exists. Source: SSC MC 22/05/2026 p5; SSC MC 08/05/2026 p7; SSC MC 16/04/2026 p6; v2.4 note (Drive: AI Solution > AI Training Materials).
A19: 8 | B19: Q3 | C19: Role workshops and labs | D19: AI Specialist | E19: HR/L&D, Coordinator | F19: =EDATE('Executive Summary'!$C$4,6) -> 46478 | G19: Not started | J19: Starts this month, then ongoing. Input: role material exists but no workshops or labs have been run. This includes the Prompting Hub role templates for BA/Dev/Tester (v1 in internal testing in Apr 2026) and BA-SPEC-KIT v0.1 on Fine-Chemical. LSG plans to build common AI skills for BA & QC first, and the MC asked to package the Hanoi BA case with training + AI drive (Action #7). Source: SSC MC 27/02/2026 p7-9; SSC MC 16/04/2026 p5; AXC MC 07/08/2026 p8-9; AXC MC 28/08/2026 p6; MoM AXC MC 28/08/2026 Action #7.
A20: 9 | B20: Q3 | C20: Add Safe AI + basic course to new-hire onboarding | D20: Coordinator | E20: HR/L&D | F20: =EDATE('Executive Summary'!$C$4,8) -> 46539 | G20: Not started
A21: 10 | B21: ongoing | C21: 30/60/90-day follow-up after each course | D21: Coordinator | E21: HR/L&D | F21: Per course | G21: Not started
A22: 11 | B22: Q4 | C22: Year review, update materials | D22: Coordinator | E22: HR/L&D | F22: =EDATE('Executive Summary'!$C$4,11) -> 46631 | G22: Not started
A23: 4.3 | C23: Knowledge sharing from real work | D23: Goal: A shared library of real work cases and a monthly sharing session. Needs first: IT provides a shared space; A case from the first pilot JD: 4.3, 4.4
A24: 12 | B24: Q2 | C24: Case template + shared space | D24: Coordinator | E24: AI leads, IT | F24: =EDATE('Executive Summary'!$C$4,5) -> 46447 | G24: Not started | J24: Input: the Prompting Hub was designed to hold 'internal real use cases' (v1 in internal testing). AXC proposes one PIC to collect and maintain AI templates and shared resources, and the ERP review found BA/QC/PM AI practices still personal, 'not yet published or reused'. No case template or shared space has been set up. Source: SSC MC 27/02/2026 p9; SSC MC 16/04/2026 p5; AI_Adoption_Summary_2Projects slide 1; AXC MC 07/08/2026 p6.
A25: 13 | B25: Q2 | C25: First case from the Engineering pilot report | D25: Coordinator | E25: AI leads, IT | F25: =EDATE('Executive Summary'!$C$4,5) -> 46447 | G25: Not started | J25: Input: earlier case write-ups exist, but none come from the Engineering pilot: 'AI in Practice - Two Projects' (BluePrint ~20% time saved per dev; HRM-Sambu ~35-40% gain, both self-reported) and the HRM-X and BluePrint AI Evidence Reports. The Hanoi BA dashboard case was recognised as best practice, to be packaged. Source: SSC MC 22/05/2026 p6, p11; MoM AXC MC 28/08/2026 s4, Decision #10, Action #7.
A26: 14 | B26: Q3 | C26: Monthly sharing session; AI leads add cases | D26: Coordinator | E26: AI leads, IT | F26: =EDATE('Executive Summary'!$C$4,6) -> 46478 | G26: Not started | J26: Starts this month, then ongoing. Input: sharing has happened ad hoc, with no monthly session: AI adoption content was presented at the 22/05 MC, material and use cases were shared with BP, and AXC worked alongside projects for 2 weeks. AI PICs are named (LSG 2, ESG 1) but there is no session schedule. Source: SSC MC 22/05/2026 p7-10; MoM AXC MC 28/08/2026 s3.3, s4; AXC MC 07/08/2026 p10.
A29: ACTIONS DONE | D29: =COUNTIF($G$11:$G$28,"Done") -> 0 | E29: ="of "&(COUNTA($B$11:$B$28))&" actions" -> of 14 actions | G29: Progress | H29: =IFERROR(SUM($H$11:$H$28)/(COUNTA($B$11:$B$28)),0) -> 0

Sheet O5 Measurement
A1: O5 - Measurement & AML
A2: Owner | C2: AXC Lead + Coordinator | F2: Status | G2: Not started
A3: How do we measure progress and impact?
A5: 1 OBJECTIVE
A6: Measure AI maturity level (AML) objectively at 3 levels: individual, team and company. Find weak areas and act on them. Analyse the link between AI use and business results, and provide the numbers for the quarterly review.
A8: 2 ACTION PLAN
A9: # | B9: Quarter | C9: Action | D9: Owner | E9: Partners | F9: Due | G9: Status | H9: % | I9: Reference document | J9: Note
A10: 5.1 | C10: AML framework with objective indicators | D10: Goal: One approved AML framework that measures AI maturity for individuals, teams and the company, using system data. Needs first: IT/PMO give data access (usage logs, Jira, Git, timesheets); Monthly usage data from license tracking is available JD: 5.1, 5.2
A11: 1 | B11: Q2 | C11: Draft levels, criteria, indicators and data sources | D11: AXC Lead | E11: HR, IT, PMO | F11: =EDATE('Executive Summary'!$C$4,3) -> 46388 | G11: In progress | J11: Draft AML framework exists: levels 1-7 drafted 16/04/2026, then a 6-axis model (AI Workload Share, Effectiveness, Coverage, AI Skill, Control, AI Assets), each axis scored 0-5 against Required/Expected. It was piloted on BluePrint, CARIS and WebCash, and the criteria were refined and shared with teams for feedback. Still missing: objective indicators and data sources. Scores are self-assessed, and each project chose its own focus criteria. Source: SSC MC 16/04/2026 p4; AXC MC 03/07/2026 p2, p9; MoM AXC MC 28/08/2026 s5.
A12: 2 | B12: Q2 | C12: Agree with HR who can see individual results and how they are used | D12: AXC Lead | E12: HR, IT, PMO | F12: =EDATE('Executive Summary'!$C$4,3) -> 46388 | G12: Not started | J12: Input: The MC decided that AML will apply at individual level and feed KPI/evaluation and hiring criteria from 2027. HR cannot measure it, so AXC must provide the method. No agreement with HR on who sees individual results has been drafted. An earlier deck flagged the risk that people fear productivity-driven KPIs and avoid transparent AI use. Source: MoM AXC MC 28/08/2026 s5, Decision #5; SSC MC 06/02/2026 p7.
A13: 3 | B13: Q2 | C13: Scoring guide | D13: AXC Lead | E13: HR, IT, PMO | F13: =EDATE('Executive Summary'!$C$4,4) -> 46419 | G13: Not started | J13: Input: AML scoring sheets exist for 3 pilot projects (Google Drive: AI Solution > AI Maturity Level: BluePrint, WebCash-HRM, CARIS). No scoring or self-assessment guide has been written or published. Source: AXC MC 28/08/2026 p9-11; v2.4 notes T2 Management #13, #14.
A14: 4 | B14: Q2 | C14: BOD approves the AML framework | D14: AXC Lead | E14: HR, IT, PMO | F14: =EDATE('Executive Summary'!$C$4,4) -> 46419 | G14: Not started | J14: Input: Leadership direction at the MC: AML level 3 is enough for now, and it is an internal scale with criteria chosen per project. This is direction, not BOD approval of a framework. Source: MoM AXC MC 28/08/2026 Decision #6.
A15: 5 | B15: ongoing | C15: Review and update the AML framework, confirmed by the BOD at the quarterly review | D15: AXC Lead | E15: HR, IT, PMO | F15: Per BOD review | G15: Not started
A16: 5.2 | C16: AML cycles drive improvement | D16: Goal: AML scored every 6 months, with an improvement plan for every team below the bar. Needs first: AML framework approved; Monthly usage data is stable; Function heads own the improvement actions; Rules for individual results agreed with HR JD: 5.3
A17: 6 | B17: Q2 | C17: Cycle 1 = baseline for team and company levels (from usage data), with gap list + improvement plans | D17: Coordinator | E17: function heads | F17: =EDATE('Executive Summary'!$C$4,5) -> 46447 | G17: Not started | J17: Input: A pilot AML round was self-assessed on 3 projects, with a gap list (Control below Required in all 3) and per-project action plans. Scores: CARIS 3.0/5 (5 of 6 axes), WebCash-HRM 2.4/5 (4 of 6), BluePrint 2.2/5 (4 of 6 on p8, 3 of 6 on p10). Conflicts: CARIS was 3.1/5 on 24/07, and the MoM records '>3.5 (~3.54)' (auto-transcript), so use the 28/08 slides. This is not yet a team/company baseline from usage data; usage data exists for 46 accounts (19 non-dev + 27 dev). Source: AXC MC 28/08/2026 p8-11; AXC MC 24/07/2026 slides 4, 9; MoM AXC MC 28/08/2026 s5.
A18: 7 | B18: ongoing | C18: Track improvement actions every month with function heads | D18: Coordinator | E18: function heads | F18: Monthly | G18: Not started
A19: 8 | B19: Q4 | C19: Cycle 2, including the individual level | D19: Coordinator | E19: function heads | F19: =EDATE('Executive Summary'!$C$4,11) -> 46631 | G19: Not started | J19: Input: The MC requires AML at individual level, not only project level, linked to KPI/evaluation from 2027. Source: MoM AXC MC 28/08/2026 s5, Decision #5.
A20: 5.3 | C20: Impact measured for pilots and company | D20: Goal: One method to measure the impact of AI on productivity, quality and working time, used for every pilot and for the company. Needs first: Access to project data (Jira, Git, timesheets); Pilot projects chosen JD: 1.4, 5.4
A21: 9 | B21: Q1 | C21: Measurement method: metrics, baseline, comparison group, how to count time saved | D21: AXC Lead | E21: PMO, Finance | F21: =EDATE('Executive Summary'!$C$4,1) -> 46327 | G21: Not started | J21: Input: MC asked AXC for (1) a method to measure the AI-related part of KPI (other companies use >=40%) for the 2027 HR evaluation and (2) expected productivity per AML level with an external benchmark (e.g. level 5 ~300%). Earlier figures are self-reported and use different metrics with no comparison group or time-saved rule: '30% overall productivity boost' (16/04), '~30-51%' effort reduction (22/05), HRM-X 27% baseline vs 52% actual with metric not stated (12/03). CV screening figures also conflict: 5-10 min to ~1 min per CV (07/08, TO-BE design), ~15 to ~5 min (28/08 p4), '~30% time saved' (MoM). The draft cost standard proposes cost per unit of completed work. Source: MoM AXC MC 28/08/2026 s3.1, s5, Actions #6, #8; SSC MC 12/03/2026 p7, p11; SSC MC 16/04/2026 p5; SSC MC 22/05/2026 p7; AXC MC 07/08/2026 p4; AXC MC 28/08/2026 p4; AI_Cost_Quota_Standard_by_Role.md R4.2.
A22: 10 | B22: ongoing | C22: Result report after each pilot | D22: AXC Lead | E22: PMO, Finance | F22: Per pilot | G22: Not started
A23: 11 | B23: Q3 | C23: Company-level analysis of AI use vs. business results (1st) | D23: AXC Lead | E23: PMO, Finance | F23: =EDATE('Executive Summary'!$C$4,8) -> 46539 | G23: Not started
A24: 12 | B24: Q4 | C24: Company-level analysis of AI use vs. business results (2nd) | D24: AXC Lead | E24: PMO, Finance | F24: =EDATE('Executive Summary'!$C$4,11) -> 46631 | G24: Not started
A27: ACTIONS DONE | D27: =COUNTIF($G$11:$G$26,"Done") -> 0 | E27: ="of "&(COUNTA($B$11:$B$26))&" actions" -> of 12 actions | G27: Progress | H27: =IFERROR(SUM($H$11:$H$26)/(COUNTA($B$11:$B$26)),0) -> 0

Sheet O6 Governance
A1: O6 - Safety & Governance
A2: Owner | C2: AXC Lead + AI Specialist + Coordinator | F2: Status | G2: Not started
A3: What are the safety limits?
A5: 1 OBJECTIVE
A6: Set principles and a policy for responsible AI use: security, personal data, IP and client confidentiality. Keep a list of approved tools and permitted use. Work with Security, IT, HR, Legal and function leaders.
A8: 2 ACTION PLAN
A9: # | B9: Quarter | C9: Action | D9: Owner | E9: Partners | F9: Due | G9: Status | H9: % | I9: Reference document | J9: Note
A10: 6.1 | C10: Governance: principles, decision table, partner roles | D10: Goal: Clear rules on who decides what for AI, and clear tasks for Security, IT, HR, Legal and function leaders. Needs first: BOD sponsor; Each partner names a contact person JD: 6.1, 6.5
A11: 1 | B11: Q1 | C11: Draft principles + decision table | D11: AXC Lead | E11: BOD, Security, IT, HR, Legal | F11: =EDATE('Executive Summary'!$C$4,0) -> 46296 | G11: Not started | J11: Input: two TO-BE options for AI account requests were proposed (AXC as monitoring layer; GM/PM + AXC co-approval with probation paid by AXC). Draft standard AXC-STD-AI-001 v0.9 (17/09/2026, awaiting approval) has an approval table: Tier 1 none, Tier 2 PM approves and AXC is notified, Tier 3 PM proposes and AXC approves. The BOD briefing sets the data-access policy condition. These cover cost and account approval only, not AI-use principles. Source: AXC MC 03/07/2026 p6-7; AI_Cost_Quota_Standard_by_Role.md §6, R6.1-R6.2; AX_BOD_Briefing_EN slide 2.
A12: 2 | B12: Q1 | C12: Agree tasks with Security, IT, HR, Legal and function leaders | D12: AXC Lead | E12: BOD, Security, IT, HR, Legal | F12: =EDATE('Executive Summary'!$C$4,1) -> 46327 | G12: Not started
A13: 3 | B13: Q1 | C13: BOD approves the principles and decision table, in the same BOD session as the strategy approval | D13: AXC Lead | E13: BOD, Security, IT, HR, Legal | F13: =EDATE('Executive Summary'!$C$4,1) -> 46327 | G13: Not started
A14: 4 | B14: ongoing | C14: Review and update the principles and decision table, confirmed by the BOD at the quarterly review | D14: AXC Lead | E14: BOD, Security, IT, HR, Legal | F14: Per BOD review | G14: Not started
A15: 6.2 | C15: AI Usage Policy | D15: Goal: One AI Usage Policy that tells staff which tools and data they may use, and protects client data, personal data and IP. Needs first: Approver named in the decision table; Approved tool list in place (before BOD approval); Security and Legal name reviewers JD: 6.2, 6.3
A16: 5 | B16: Q1 | C16: Data categories (e.g. public, internal, confidential, personal), confirmed by Legal under the applicable law | D16: AI Specialist | E16: Security, Legal | F16: =EDATE('Executive Summary'!$C$4,0) -> 46296 | G16: Not started | J16: Input: a real personal-data case exists. The HR CV screening tool pulls candidate phone and email from CVs. CLT policy blocks auto-scripts on Drive files, and Blueprint/HR does not allow CV scanning. No data categories are defined yet. Source: AXC MC 07/08/2026 p4; AXC MC 28/08/2026 p4; MoM AXC MC 28/08/2026 s3.1.
A17: 6 | B17: Q1 | C17: Draft policy | D17: AI Specialist | E17: Security, Legal | F17: =EDATE('Executive Summary'!$C$4,1) -> 46327 | G17: In progress | J17: Parts of the policy are drafted: the prohibited-actions policy (Cursor, Claude) and the overspend process, both drafted 17/09/2026 (reported by AXC Lead). Draft standard v0.9 adds rules that ban personal accounts (Claude Max, Claude Pro, ChatGPT Plus) for company work and require hard spending limits; data use rules are not covered yet. Source: AXC Lead 29/09/2026 (Drive: AI Solution > AI security); AI_Cost_Quota_Standard_by_Role.md R7.1-R7.2.
A18: 7 | B18: Q1 | C18: Legal and Security review the policy; BOD approves it | D18: AI Specialist | E18: Security, Legal | F18: =EDATE('Executive Summary'!$C$4,2) -> 46357 | G18: Not started
A19: 8 | B19: Q1 | C19: Pilot team confirms reading the policy at the Safe AI training | D19: Coordinator | E19: Security, Legal | F19: =EDATE('Executive Summary'!$C$4,2) -> 46357 | G19: Not started
A20: 9 | B20: Q2 | C20: All staff confirm reading the policy at the Safe AI training | D20: Coordinator | E20: Security, Legal | F20: =EDATE('Executive Summary'!$C$4,5) -> 46447 | G20: Not started
A21: 10 | B21: Q1 | C21: AI permissions confirmed for pilot clients, with the Delivery head and Legal | D21: Coordinator | E21: Security, Legal | F21: =EDATE('Executive Summary'!$C$4,2) -> 46357 | G21: Not started
A22: 11 | B22: Q2 | C22: AI permissions recorded for all clients, with the Delivery head and Legal | D22: Coordinator | E22: Security, Legal | F22: =EDATE('Executive Summary'!$C$4,5) -> 46447 | G22: Not started
A23: 12 | B23: ongoing | C23: Review and update the policy, confirmed by the BOD at the quarterly review | D23: AI Specialist | E23: Security, Legal | F23: Per BOD review | G23: Not started
A24: 6.3 | C24: Incident handling & compliance checks | D24: Goal: A working process to report and handle AI incidents, and regular checks that the policy is followed. Needs first: AI Usage Policy issued; Security adds AI incidents to its current process JD: 6.2, 6.3
A25: 13 | B25: Q1 | C25: Reporting channel + handling process, ready before the first pilot | D25: AI Specialist | E25: Security, IT | F25: =EDATE('Executive Summary'!$C$4,2) -> 46357 | G25: Not started | J25: Input: one incident, an unauthorised $330 Claude 'Gift' charge, was handled ad hoc. An automated billing email flagged it and Anthropic confirmed a refund. An overspend process was drafted 17/09/2026, but no general AI incident channel exists. Source: SSC MC 08/05/2026 p6; AXC Lead 29/09/2026.
A26: 14 | B26: Q2 | C26: First compliance check | D26: AI Specialist | E26: Security, IT | F26: =EDATE('Executive Summary'!$C$4,5) -> 46447 | G26: Not started | J26: Input: 15 Claude Max accounts are counted in use (out of 180), and draft rule R7.1 bans personal accounts including Claude Max for company work. These are the first items to check once the rule is approved. Source: AXC MC 28/08/2026 p7; AI_Cost_Quota_Standard_by_Role.md R7.1.
A27: 15 | B27: ongoing | C27: Check every quarter, including unapproved tools in use (with IT); results feed the policy update | D27: AI Specialist | E27: Security, IT | F27: Quarterly | G27: Not started
A30: ACTIONS DONE | D30: =COUNTIF($G$11:$G$29,"Done") -> 0 | E30: ="of "&(COUNTA($B$11:$B$29))&" actions" -> of 15 actions | G30: Progress | H30: =IFERROR(SUM($H$11:$H$29)/(COUNTA($B$11:$B$29)),0) -> 0

Sheet Meeting Log
A1: MEETING LOG - record of approvals, confirmations and reports
A2: Add one row each time something is approved, confirmed, reported or deferred at a meeting. This is the written record of what was agreed, so decisions do not have to be rebuilt from memory later.
A4: 1 HOW TO FILL THIS IN
A5: 1 | B5: One row per decision, not one row per meeting. If a meeting approves two things, that is two rows.
A6: 2 | B6: Outcome says what happened: Approved, Confirmed, Reported (information only), Deferred, Rejected.
A7: 3 | B7: Write what was actually said - keep the original wording.
A8: 4 | B8: If the decision creates work, put it in Follow-up action with an owner and a due date, and set Status to Open. Change it to Done once closed.
A9: 5 | B9: Use role names rather than personal names in the Owner column.
A11: 2 LOG
A12: # | B12: Date | C12: Meeting | D12: Objective | E12: Outcome | F12: What was decided or reported | G12: Follow-up action | H12: Owner (role) | I12: Due | J12: Status
A13: 1 | B13: 2026-10-15 | C13: MC meeting | D13: O1 | E13: Approved | F13: EXAMPLE ROW - delete before use. AI strategy and 12-month roadmap approved; asked to start with the Engineering pilot. | G13: Fix quarterly review dates | H13: AXC Lead | I13: 2026-10-31 | J13: Open
A14: 2
A15: 3
A16: 4
A17: 5
A18: 6
A19: 7
A20: 8
A21: 9
A22: 10
A23: 11
A24: 12
A25: 13
... A43: 31

Sheet Job Description
A1: AI Transformation – Job Description
A2: Source of the objectives. 'Covered by' shows the objective detail that delivers each duty.
A4: Ref | B4: Duty | C4: Covered by
A5: 1. AI Transformation Strategy & Roadmap
A6: 1.1 | B6: Define and drive the company-wide AI Transformation Strategy and Roadmap, aligned with business priorities. | C6: 1.1
A7: 1.2 | B7: Identify and prioritize high-impact AI use cases across Engineering, QA, BA, Project Management, Delivery, and Corporate Functions. | C7: 1.1, 2.1, 2.2, 2.3
A8: 1.3 | B8: Go beyond tool adoption by redesigning work processes and ways of working around AI. | C8: 2.1, 2.2, 2.3
A9: 1.4 | B9: Continuously evaluate the impact of AI on productivity, quality, working time, and operational effectiveness. | C9: 5.3
A10: 1.5 | B10: Work closely with senior leadership and functional leaders to translate transformation goals into actionable initiatives. | C10: 1.2
A11: 2. AI-Enabled Process Transformation
A12: 2.1 | B12: Analyze existing workflows and identify opportunities where AI can improve productivity, quality, and efficiency. | C12: 2.1, 2.2, 2.3
A13: 2.2 | B13: Design AI-enabled workflows for coding, code review, testing, documentation, requirements analysis, project management, reporting, and communication. | C13: 2.1, 2.2, 2.3
A14: 2.3 | B14: Lead pilots with business and delivery teams to validate actual impact in real working environments. | C14: 2.4
A15: 2.4 | B15: Convert proven use cases into repeatable best practices and standard workflows for company-wide adoption. | C15: 2.4
A16: 2.5 | B16: Focus on measurable business outcomes rather than AI adoption for its own sake. | C16: 2.4
A17: 3. AI Tool Evaluation & Adoption
A18: 3.1 | B18: Continuously evaluate external AI tools and services, including solutions such as ChatGPT, Claude, GitHub Copilot, and Cursor. | C18: 3.1
A19: 3.2 | B19: Assess tools based on business applicability, productivity impact, user experience, cost, information security, and data protection. | C19: 3.1
A20: 3.3 | B20: Lead pilots and Proof-of-Value initiatives, and define the appropriate tools and usage models by function and role. | C20: 3.1, 3.2
A21: 3.4 | B21: Manage licenses and usage, and analyze adoption and impact relative to cost. | C21: 3.2, 3.3
A22: 3.5 | B22: Prioritize external tools while assessing internal AI infrastructure only when justified by security, cost, integration, or strategic needs. | C22: 3.1
A23: 4. Workforce AI Capability Development
A24: 4.1 | B24: Develop and operate a company-wide AI Capability Development Program. | C24: 4.1
A25: 4.2 | B25: Define role-based AI competencies and practical learning paths for employees. | C25: 4.1
A26: 4.3 | B26: Deliver training, workshops, hands-on programs, and internal knowledge-sharing mechanisms. | C26: 4.2, 4.3
A27: 4.4 | B27: Capture and disseminate best practices grounded in real work cases. | C27: 4.3
